Workbook

Sheet Dashboard
A1: TABLERO DE RELEVADORES DE PROTECCIÓN Y MEDICIÓN
A2: Refinería Olmeca · SICM Eléctrico · Fuente: PM_RELEVADOR.xlsx (SAP PM, 1,960 equipos, perfil ZPM000263)
A4: Sector (filtro) | C4: (Todos) | G4: Celdas amarillas = seleccione de la lista. El sector filtra KPIs, marcas, modelos, subestaciones y funciones; la gráfica por sector y la de marca × sector muestran siempre todos.
A5: Criterio de sector | C5: Ubicación técnica | G5: Criterio de sector: "Ubicación técnica" toma el sector del código de la ubicación técnica; "Local SAP" usa la columna Local. Difieren en 27 equipos de PRA1 (SE-02), ver hoja Calidad_Datos.
A7: RELEVADORES (filtro) | F7: MARCAS DISTINTAS | K7: MODELOS DISTINTOS (normalizados) | P7: SUBESTACIONES CON RELEVADORES
A8: =COUNTIFS(d_Sector,crit_sector) -> 1960 | F8: =COUNTIFS(Calc!$N$4:$N$13,">0",Calc!$M$4:$M$13,"<>SIN DATO") -> 9 | K8: =COUNTIFS(Calc!$T$4:$T$57,">0",Calc!$R$4:$R$57,"<>SIN DATO") -> 53 | P8: =COUNTIF(Calc!$AB$4:$AB$43,">0") -> 40
A9: =IF($A$8=0,"–",TEXT(COUNTIFS(d_Tipo,"Subestación eléctrica",d_Sector,crit_sector),"#,##0")&" en subestaciones · "&TEXT(COUNTIFS(d_Tipo,"Área de proceso",d_Sector,crit_sector),"#,##0")&" en áreas de proceso") -> 1,416 en subestaciones · 544 en áreas de proceso | F9: ="Marcas normalizadas: GE y GENERAL ELECTRIC unificadas" -> Marcas normalizadas: GE y GENERAL ELECTRIC unificadas | K9: ="Modelos con variantes de escritura unificadas" -> Modelos con variantes de escritura unificadas | P9: =IF($A$8=0,"–",TEXT(COUNTIFS(d_Tipo,"Subestación eléctrica",d_Sector,crit_sector)/$A$8,"0%")&" en subestaciones eléctricas") -> 72% en subestaciones eléctricas
A10: MARCA LÍDER | F10: SIN MARCA O MODELO | K10: MODELOS GENÉRICOS / INCOMPLETOS | P10: EN ÁREA CLASE I DIV. II
A11: =IF($A$8=0,"–",INDEX(Calc!$M$4:$M$13,MATCH(MAX(Calc!$N$4:$N$13),Calc!$N$4:$N$13,0))&" · "&TEXT(MAX(Calc!$N$4:$N$13)/$A$8,"0%")) -> ABB · 42% | F11: =COUNTIFS(d_Completo,"No",d_Sector,crit_sector) -> 51 | K11: =COUNTIFS(d_Gen,"Sí",d_Sector,crit_sector) -> 699 | P11: =COUNTIFS(d_Clase,"CLASE I DIVISION II",d_Sector,crit_sector) -> 156
A12: ="Marca con más relevadores en el filtro" -> Marca con más relevadores en el filtro | F12: =IF($A$8=0,"–",TEXT(F11/$A$8,"0.0%")&" del total (ver Calidad_Datos)") -> 2.6% del total (ver Calidad_Datos) | K12: =IF($A$8=0,"–",TEXT(K11/$A$8,"0.0%")&" del total") -> 35.7% del total | P12: =IF($A$8=0,"–",TEXT(P11/$A$8,"0.0%")&" del total") -> 8.0% del total

Sheet Pivot_Marca_Modelo
A1: TABLA DINÁMICA · RELEVADORES POR MARCA Y MODELO, CLASIFICADOS POR SECTOR
A2: Fórmulas COUNTIFS sobre la hoja Datos: se recalculan al cambiar los filtros o los datos. Cada marca lleva su total y debajo sus modelos.
A3: Subestación | B3: (Todas) | D3: criterio: | E3: =IF($B$3="(Todas)","*",$B$3) -> *
A4: Tipo de ubicación | B4: (Todos) | D4: criterio: | E4: =IF($B$4="(Todos)","*",$B$4) -> *
A6: Marca | B6: Modelo | C6: Sector 1 | D6: Sector 2 | E6: Sector 3 | F6: Sector 4 | G6: Sector 5 | H6: Sector 6 | I6: Sector 7 | J6: Sector 8 | K6: Total | L6: % del total
A7: ABB | B7: Total ABB | C7: =COUNTIFS(d_Marca,$A7,d_Sector,C$6,d_Subest,$E$3,d_Tipo,$E$4) -> 214 | D7: =COUNTIFS(d_Marca,$A7,d_Sector,D$6,d_Subest,$E$3,d_Tipo,$E$4) -> 123 | E7: =COUNTIFS(d_Marca,$A7,d_Sector,E$6,d_Subest,$E$3,d_Tipo,$E$4) -> 48 | F7: =COUNTIFS(d_Marca,$A7,d_Sector,F$6,d_Subest,$E$3,d_Tipo,$E$4) -> 23 | G7: =COUNTIFS(d_Marca,$A7,d_Sector,G$6,d_Subest,$E$3,d_Tipo,$E$4) -> 36 | H7: =COUNTIFS(d_Marca,$A7,d_Sector,H$6,d_Subest,$E$3,d_Tipo,$E$4) -> 132 | I7: =COUNTIFS(d_Marca,$A7,d_Sector,I$6,d_Subest,$E$3,d_Tipo,$E$4) -> 8 | J7: =COUNTIFS(d_Marca,$A7,d_Sector,J$6,d_Subest,$E$3,d_Tipo,$E$4) -> 232 | K7: =SUM(C7:J7) -> 816 | L7: =IF($K$71=0,0,K7/$K$71) -> 0.41632653
A8: ABB | B8: 1AFFAEAGNEC5BNA11G | C8: =COUNTIFS(d_Marca,$A8,d_Modelo,$B8,d_Sector,C$6,d_Subest,$E$3,d_Tipo,$E$4) -> 147 | D8: =COUNTIFS(d_Marca,$A8,d_Modelo,$B8,d_Sector,D$6,d_Subest,$E$3,d_Tipo,$E$4) -> 36 | E8: =COUNTIFS(d_Marca,$A8,d_Modelo,$B8,d_Sector,E$6,d_Subest,$E$3,d_Tipo,$E$4) -> 0 | F8: =COUNTIFS(d_Marca,$A8,d_Modelo,$B8,d_Sector,F$6,d_Subest,$E$3,d_Tipo,$E$4) -> 0 | G8: =COUNTIFS(d_Marca,$A8,d_Modelo,$B8,d_Sector,G$6,d_Subest,$E$3,d_Tipo,$E$4) -> 0 | H8: =COUNTIFS(d_Marca,$A8,d_Modelo,$B8,d_Sector,H$6,d_Subest,$E$3,d_Tipo,$E$4) -> 0 | I8: =COUNTIFS(d_Marca,$A8,d_Modelo,$B8,d_Sector,I$6,d_Subest,$E$3,d_Tipo,$E$4) -> 0 | J8: =COUNTIFS(d_Marca,$A8,d_Modelo,$B8,d_Sector,J$6,d_Subest,$E$3,d_Tipo,$E$4) -> 1 | K8: =SUM(C8:J8) -> 184 | L8: =IF($K$71=0,0,K8/$K$71) -> 0.093877551
A9: ABB | B9: REF615A_1G | C9: =COUNTIFS(d_Marca,$A9,d_Modelo,$B9,d_Sector,C$6,d_Subest,$E$3,d_Tipo,$E$4) -> 0 | D9: =COUNTIFS(d_Marca,$A9,d_Modelo,$B9,d_Sector,D$6,d_Subest,$E$3,d_Tipo,$E$4) -> 0 | E9: =COUNTIFS(d_Marca,$A9,d_Modelo,$B9,d_Sector,E$6,d_Subest,$E$3,d_Tipo,$E$4) -> 0 | F9: =COUNTIFS(d_Marca,$A9,d_Modelo,$B9,d_Sector,F$6,d_Subest,$E$3,d_Tipo,$E$4) -> 0 | G9: =COUNTIFS(d_Marca,$A9,d_Modelo,$B9,d_Sector,G$6,d_Subest,$E$3,d_Tipo,$E$4) -> 0 | H9: =COUNTIFS(d_Marca,$A9,d_Modelo,$B9,d_Sector,H$6,d_Subest,$E$3,d_Tipo,$E$4) -> 69 | I9: =COUNTIFS(d_Marca,$A9,d_Modelo,$B9,d_Sector,I$6,d_Subest,$E$3,d_Tipo,$E$4) -> 0 | J9: =COUNTIFS(d_Marca,$A9,d_Modelo,$B9,d_Sector,J$6,d_Subest,$E$3,d_Tipo,$E$4) -> 98 | K9: =SUM(C9:J9) -> 167 | L9: =IF($K$71=0,0,K9/$K$71) -> 0.085204082
A10: ABB | B10: 1AMEBCADNEC5BNN11G | C10: =COUNTIFS(d_Marca,$A10,d_Modelo,$B10,d_Sector,C$6,d_Subest,$E$3,d_Tipo,$E$4) -> 38 | D10: =COUNTIFS(d_Marca,$A10,d_Modelo,$B10,d_Sector,D$6,d_Subest,$E$3,d_Tipo,$E$4) -> 47 | E10: =COUNTIFS(d_Marca,$A10,d_Modelo,$B10,d_Sector,E$6,d_Subest,$E$3,d_Tipo,$E$4) -> 0 | F10: =COUNTIFS(d_Marca,$A10,d_Modelo,$B10,d_Sector,F$6,d_Subest,$E$3,d_Tipo,$E$4) -> 0 | G10: =COUNTIFS(d_Marca,$A10,d_Modelo,$B10,d_Sector,G$6,d_Subest,$E$3,d_Tipo,$E$4) -> 0 | H10: =COUNTIFS(d_Marca,$A10,d_Modelo,$B10,d_Sector,H$6,d_Subest,$E$3,d_Tipo,$E$4) -> 0 | I10: =COUNTIFS(d_Marca,$A10,d_Modelo,$B10,d_Sector,I$6,d_Subest,$E$3,d_Tipo,$E$4) -> 0 | J10: =COUNTIFS(d_Marca,$A10,d_Modelo,$B10,d_Sector,J$6,d_Subest,$E$3,d_Tipo,$E$4) -> 0 | K10: =SUM(C10:J10) -> 85 | L10: =IF($K$71=0,0,K10/$K$71) -> 0.043367347
A11: ABB | B11: REF | C11: =COUNTIFS(d_Marca,$A11,d_Modelo,$B11,d_Sector,C$6,d_Subest,$E$3,d_Tipo,$E$4) -> 0 | D11: =COUNTIFS(d_Marca,$A11,d_Modelo,$B11,d_Sector,D$6,d_Subest,$E$3,d_Tipo,$E$4) -> 0 | E11: =COUNTIFS(d_Marca,$A11,d_Modelo,$B11,d_Sector,E$6,d_Subest,$E$3,d_Tipo,$E$4) -> 29 | F11: =COUNTIFS(d_Marca,$A11,d_Modelo,$B11,d_Sector,F$6,d_Subest,$E$3,d_Tipo,$E$4) -> 11 | G11: =COUNTIFS(d_Marca,$A11,d_Modelo,$B11,d_Sector,G$6,d_Subest,$E$3,d_Tipo,$E$4) -> 23 | H11: =COUNTIFS(d_Marca,$A11,d_Modelo,$B11,d_Sector,H$6,d_Subest,$E$3,d_Tipo,$E$4) -> 0 | I11: =COUNTIFS(d_Marca,$A11,d_Modelo,$B11,d_Sector,I$6,d_Subest,$E$3,d_Tipo,$E$4) -> 4 | J11: =COUNTIFS(d_Marca,$A11,d_Modelo,$B11,d_Sector,J$6,d_Subest,$E$3,d_Tipo,$E$4) -> 0 | K11: =SUM(C11:J11) -> 67 | L11: =IF($K$71=0,0,K11/$K$71) -> 0.034183673
A12: ABB | B12: REA 101 | C12: =COUNTIFS(d_Marca,$A12,d_Modelo,$B12,d_Sector,C$6,d_Subest,$E$3,d_Tipo,$E$4) -> 0 | D12: =COUNTIFS(d_Marca,$A12,d_Modelo,$B12,d_Sector,D$6,d_Subest,$E$3,d_Tipo,$E$4) -> 0 | E12: =COUNTIFS(d_Marca,$A12,d_Modelo,$B12,d_Sector,E$6,d_Subest,$E$3,d_Tipo,$E$4) -> 0 | F12: =COUNTIFS(d_Marca,$A12,d_Modelo,$B12,d_Sector,F$6,d_Subest,$E$3,d_Tipo,$E$4) -> 0 | G12: =COUNTIFS(d_Marca,$A12,d_Modelo,$B12,d_Sector,G$6,d_Subest,$E$3,d_Tipo,$E$4) -> 0 | H12: =COUNTIFS(d_Marca,$A12,d_Modelo,$B12,d_Sector,H$6,d_Subest,$E$3,d_Tipo,$E$4) -> 22 | I12: =COUNTIFS(d_Marca,$A12,d_Modelo,$B12,d_Sector,I$6,d_Subest,$E$3,d_Tipo,$E$4) -> 0 | J12: =COUNTIFS(d_Marca,$A12,d_Modelo,$B12,d_Sector,J$6,d_Subest,$E$3,d_Tipo,$E$4) -> 37 | K12: =SUM(C12:J12) -> 59 | L12: =IF($K$71=0,0,K12/$K$71) -> 0.030102041
A13: ABB | B13: REM615A_1G | C13: =COUNTIFS(d_Marca,$A13,d_Modelo,$B13,d_Sector,C$6,d_Subest,$E$3,d_Tipo,$E$4) -> 0 | D13: =COUNTIFS(d_Marca,$A13,d_Modelo,$B13,d_Sector,D$6,d_Subest,$E$3,d_Tipo,$E$4) -> 0 | E13: =COUNTIFS(d_Marca,$A13,d_Modelo,$B13,d_Sector,E$6,d_Subest,$E$3,d_Tipo,$E$4) -> 0 | F13: =COUNTIFS(d_Marca,$A13,d_Modelo,$B13,d_Sector,F$6,d_Subest,$E$3,d_Tipo,$E$4) -> 0 | G13: =COUNTIFS(d_Marca,$A13,d_Modelo,$B13,d_Sector,G$6,d_Subest,$E$3,d_Tipo,$E$4) -> 0 | H13: =COUNTIFS(d_Marca,$A13,d_Modelo,$B13,d_Sector,H$6,d_Subest,$E$3,d_Tipo,$E$4) -> 10 | I13: =COUNTIFS(d_Marca,$A13,d_Modelo,$B13,d_Sector,I$6,d_Subest,$E$3,d_Tipo,$E$4) -> 0 | J13: =COUNTIFS(d_Marca,$A13,d_Modelo,$B13,d_Sector,J$6,d_Subest,$E$3,d_Tipo,$E$4) -> 47 | K13: =SUM(C13:J13) -> 57 | L13: =IF($K$71=0,0,K13/$K$71) -> 0.029081633
A14: ABB | B14: 1AFPAKAKNGC5BNN11G | C14: =COUNTIFS(d_Marca,$A14,d_Modelo,$B14,d_Sector,C$6,d_Subest,$E$3,d_Tipo,$E$4) -> 18 | D14: =COUNTIFS(d_Marca,$A14,d_Modelo,$B14,d_Sector,D$6,d_Subest,$E$3,d_Tipo,$E$4) -> 15 | E14: =COUNTIFS(d_Marca,$A14,d_Modelo,$B14,d_Sector,E$6,d_Subest,$E$3,d_Tipo,$E$4) -> 0 | F14: =COUNTIFS(d_Marca,$A14,d_Modelo,$B14,d_Sector,F$6,d_Subest,$E$3,d_Tipo,$E$4) -> 0 | G14: =COUNTIFS(d_Marca,$A14,d_Modelo,$B14,d_Sector,G$6,d_Subest,$E$3,d_Tipo,$E$4) -> 0 | H14: =COUNTIFS(d_Marca,$A14,d_Modelo,$B14,d_Sector,H$6,d_Subest,$E$3,d_Tipo,$E$4) -> 0 | I14: =COUNTIFS(d_Marca,$A14,d_Modelo,$B14,d_Sector,I$6,d_Subest,$E$3,d_Tipo,$E$4) -> 0 | J14: =COUNTIFS(d_Marca,$A14,d_Modelo,$B14,d_Sector,J$6,d_Subest,$E$3,d_Tipo,$E$4) -> 0 | K14: =SUM(C14:J14) -> 33 | L14: =IF($K$71=0,0,K14/$K$71) -> 0.016836735
A15: ABB | B15: RET615A_1G | C15: =COUNTIFS(d_Marca,$A15,d_Modelo,$B15,d_Sector,C$6,d_Subest,$E$3,d_Tipo,$E$4) -> 0 | D15: =COUNTIFS(d_Marca,$A15,d_Modelo,$B15,d_Sector,D$6,d_Subest,$E$3,d_Tipo,$E$4) -> 0 | E15: =COUNTIFS(d_Marca,$A15,d_Modelo,$B15,d_Sector,E$6,d_Subest,$E$3,d_Tipo,$E$4) -> 0 | F15: =COUNTIFS(d_Marca,$A15,d_Modelo,$B15,d_Sector,F$6,d_Subest,$E$3,d_Tipo,$E$4) -> 0 | G15: =COUNTIFS(d_Marca,$A15,d_Modelo,$B15,d_Sector,G$6,d_Subest,$E$3,d_Tipo,$E$4) -> 0 | H15: =COUNTIFS(d_Marca,$A15,d_Modelo,$B15,d_Sector,H$6,d_Subest,$E$3,d_Tipo,$E$4) -> 6 | I15: =COUNTIFS(d_Marca,$A15,d_Modelo,$B15,d_Sector,I$6,d_Subest,$E$3,d_Tipo,$E$4) -> 0 | J15: =COUNTIFS(d_Marca,$A15,d_Modelo,$B15,d_Sector,J$6,d_Subest,$E$3,d_Tipo,$E$4) -> 23 | K15: =SUM(C15:J15) -> 29 | L15: =IF($K$71=0,0,K15/$K$71) -> 0.014795918
A16: ABB | B16: REM | C16: =COUNTIFS(d_Marca,$A16,d_Modelo,$B16,d_Sector,C$6,d_Subest,$E$3,d_Tipo,$E$4) -> 0 | D16: =COUNTIFS(d_Marca,$A16,d_Modelo,$B16,d_Sector,D$6,d_Subest,$E$3,d_Tipo,$E$4) -> 0 | E16: =COUNTIFS(d_Marca,$A16,d_Modelo,$B16,d_Sector,E$6,d_Subest,$E$3,d_Tipo,$E$4) -> 9 | F16: =COUNTIFS(d_Marca,$A16,d_Modelo,$B16,d_Sector,F$6,d_Subest,$E$3,d_Tipo,$E$4) -> 5 | G16: =COUNTIFS(d_Marca,$A16,d_Modelo,$B16,d_Sector,G$6,d_Subest,$E$3,d_Tipo,$E$4) -> 6 | H16: =COUNTIFS(d_Marca,$A16,d_Modelo,$B16,d_Sector,H$6,d_Subest,$E$3,d_Tipo,$E$4) -> 0 | I16: =COUNTIFS(d_Marca,$A16,d_Modelo,$B16,d_Sector,I$6,d_Subest,$E$3,d_Tipo,$E$4) -> 4 | J16: =COUNTIFS(d_Marca,$A16,d_Modelo,$B16,d_Sector,J$6,d_Subest,$E$3,d_Tipo,$E$4) -> 0 | K16: =SUM(C16:J16) -> 24 | L16: =IF($K$71=0,0,K16/$K$71) -> 0.012244898
A17: ABB | B17: REF615_1G | C17: =COUNTIFS(d_Marca,$A17,d_Modelo,$B17,d_Sector,C$6,d_Subest,$E$3,d_Tipo,$E$4) -> 0 | D17: =COUNTIFS(d_Marca,$A17,d_Modelo,$B17,d_Sector,D$6,d_Subest,$E$3,d_Tipo,$E$4) -> 0 | E17: =COUNTIFS(d_Marca,$A17,d_Modelo,$B17,d_Sector,E$6,d_Subest,$E$3,d_Tipo,$E$4) -> 0 | F17: =COUNTIFS(d_Marca,$A17,d_Modelo,$B17,d_Sector,F$6,d_Subest,$E$3,d_Tipo,$E$4) -> 0 | G17: =COUNTIFS(d_Marca,$A17,d_Modelo,$B17,d_Sector,G$6,d_Subest,$E$3,d_Tipo,$E$4) -> 0 | H17: =COUNTIFS(d_Marca,$A17,d_Modelo,$B17,d_Sector,H$6,d_Subest,$E$3,d_Tipo,$E$4) -> 18 | I17: =COUNTIFS(d_Marca,$A17,d_Modelo,$B17,d_Sector,I$6,d_Subest,$E$3,d_Tipo,$E$4) -> 0 | J17: =COUNTIFS(d_Marca,$A17,d_Modelo,$B17,d_Sector,J$6,d_Subest,$E$3,d_Tipo,$E$4) -> 0 | K17: =SUM(C17:J17) -> 18 | L17: =IF($K$71=0,0,K17/$K$71) -> 0.0091836735
A18: ABB | B18: 1ATBBABBNEC5BNN11G | C18: =COUNTIFS(d_Marca,$A18,d_Modelo,$B18,d_Sector,C$6,d_Subest,$E$3,d_Tipo,$E$4) -> 5 | D18: =COUNTIFS(d_Marca,$A18,d_Modelo,$B18,d_Sector,D$6,d_Subest,$E$3,d_Tipo,$E$4) -> 11 | E18: =COUNTIFS(d_Marca,$A18,d_Modelo,$B18,d_Sector,E$6,d_Subest,$E$3,d_Tipo,$E$4) -> 0 | F18: =COUNTIFS(d_Marca,$A18,d_Modelo,$B18,d_Sector,F$6,d_Subest,$E$3,d_Tipo,$E$4) -> 0 | G18: =COUNTIFS(d_Marca,$A18,d_Modelo,$B18,d_Sector,G$6,d_Subest,$E$3,d_Tipo,$E$4) -> 0 | H18: =COUNTIFS(d_Marca,$A18,d_Modelo,$B18,d_Sector,H$6,d_Subest,$E$3,d_Tipo,$E$4) -> 0 | I18: =COUNTIFS(d_Marca,$A18,d_Modelo,$B18,d_Sector,I$6,d_Subest,$E$3,d_Tipo,$E$4) -> 0 | J18: =COUNTIFS(d_Marca,$A18,d_Modelo,$B18,d_Sector,J$6,d_Subest,$E$3,d_Tipo,$E$4) -> 0 | K18: =SUM(C18:J18) -> 16 | L18: =IF($K$71=0,0,K18/$K$71) -> 0.0081632653
A19: ABB | B19: REA | C19: =COUNTIFS(d_Marca,$A19,d_Modelo,$B19,d_Sector,C$6,d_Subest,$E$3,d_Tipo,$E$4) -> 0 | D19: =COUNTIFS(d_Marca,$A19,d_Modelo,$B19,d_Sector,D$6,d_Subest,$E$3,d_Tipo,$E$4) -> 0 | E19: =COUNTIFS(d_Marca,$A19,d_Modelo,$B19,d_Sector,E$6,d_Subest,$E$3,d_Tipo,$E$4) -> 6 | F19: =COUNTIFS(d_Marca,$A19,d_Modelo,$B19,d_Sector,F$6,d_Subest,$E$3,d_Tipo,$E$4) -> 5 | G19: =COUNTIFS(d_Marca,$A19,d_Modelo,$B19,d_Sector,G$6,d_Subest,$E$3,d_Tipo,$E$4) -> 5 | H19: =COUNTIFS(d_Marca,$A19,d_Modelo,$B19,d_Sector,H$6,d_Subest,$E$3,d_Tipo,$E$4) -> 0 | I19: =COUNTIFS(d_Marca,$A19,d_Modelo,$B19,d_Sector,I$6,d_Subest,$E$3,d_Tipo,$E$4) -> 0 | J19: =COUNTIFS(d_Marca,$A19,d_Modelo,$B19,d_Sector,J$6,d_Subest,$E$3,d_Tipo,$E$4) -> 0 | K19: =SUM(C19:J19) -> 16 | L19: =IF($K$71=0,0,K19/$K$71) -> 0.0081632653
... A26: ABB | B26: REM620A_F | C26: =COUNTIFS(d_Marca,$A26,d_Modelo,$B26,d_Sector,C$6,d_Subest,$E$3,d_Tipo,$E$4) -> 0 | D26: =COUNTIFS(d_Marca,$A26,d_Modelo,$B26,d_Sector,D$6,d_Subest,$E$3,d_Tipo,$E$4) -> 0 | E26: =COUNTIFS(d_Marca,$A26,d_Modelo,$B26,d_Sector,E$6,d_Subest,$E$3,d_Tipo,$E$4) -> 0 | F26: =COUNTIFS(d_Marca,$A26,d_Modelo,$B26,d_Sector,F$6,d_Subest,$E$3,d_Tipo,$E$4) -> 0 | G26: =COUNTIFS(d_Marca,$A26,d_Modelo,$B26,d_Sector,G$6,d_Subest,$E$3,d_Tipo,$E$4) -> 0 | H26: =COUNTIFS(d_Marca,$A26,d_Modelo,$B26,d_Sector,H$6,d_Subest,$E$3,d_Tipo,$E$4) -> 0 | I26: =COUNTIFS(d_Marca,$A26,d_Modelo,$B26,d_Sector,I$6,d_Subest,$E$3,d_Tipo,$E$4) -> 0 | J26: =COUNTIFS(d_Marca,$A26,d_Modelo,$B26,d_Sector,J$6,d_Subest,$E$3,d_Tipo,$E$4) -> 5 | K26: =SUM(C26:J26) -> 5 | L26: =IF($K$71=0,0,K26/$K$71) -> 0.0025510204
A27: SEL | B27: Total SEL | C27: =COUNTIFS(d_Marca,$A27,d_Sector,C$6,d_Subest,$E$3,d_Tipo,$E$4) -> 10 | D27: =COUNTIFS(d_Marca,$A27,d_Sector,D$6,d_Subest,$E$3,d_Tipo,$E$4) -> 20 | E27: =COUNTIFS(d_Marca,$A27,d_Sector,E$6,d_Subest,$E$3,d_Tipo,$E$4) -> 26 | F27: =COUNTIFS(d_Marca,$A27,d_Sector,F$6,d_Subest,$E$3,d_Tipo,$E$4) -> 50 | G27: =COUNTIFS(d_Marca,$A27,d_Sector,G$6,d_Subest,$E$3,d_Tipo,$E$4) -> 51 | H27: =COUNTIFS(d_Marca,$A27,d_Sector,H$6,d_Subest,$E$3,d_Tipo,$E$4) -> 51 | I27: =COUNTIFS(d_Marca,$A27,d_Sector,I$6,d_Subest,$E$3,d_Tipo,$E$4) -> 6 | J27: =COUNTIFS(d_Marca,$A27,d_Sector,J$6,d_Subest,$E$3,d_Tipo,$E$4) -> 131 | K27: =SUM(C27:J27) -> 345 | L27: =IF($K$71=0,0,K27/$K$71) -> 0.17602041
A28: SEL | B28: SEL-735 | C28: =COUNTIFS(d_Marca,$A28,d_Modelo,$B28,d_Sector,C$6,d_Subest,$E$3,d_Tipo,$E$4) -> 8 | D28: =COUNTIFS(d_Marca,$A28,d_Modelo,$B28,d_Sector,D$6,d_Subest,$E$3,d_Tipo,$E$4) -> 0 | E28: =COUNTIFS(d_Marca,$A28,d_Modelo,$B28,d_Sector,E$6,d_Subest,$E$3,d_Tipo,$E$4) -> 0 | F28: =COUNTIFS(d_Marca,$A28,d_Modelo,$B28,d_Sector,F$6,d_Subest,$E$3,d_Tipo,$E$4) -> 0 | G28: =COUNTIFS(d_Marca,$A28,d_Modelo,$B28,d_Sector,G$6,d_Subest,$E$3,d_Tipo,$E$4) -> 0 | H28: =COUNTIFS(d_Marca,$A28,d_Modelo,$B28,d_Sector,H$6,d_Subest,$E$3,d_Tipo,$E$4) -> 51 | I28: =COUNTIFS(d_Marca,$A28,d_Modelo,$B28,d_Sector,I$6,d_Subest,$E$3,d_Tipo,$E$4) -> 0 | J28: =COUNTIFS(d_Marca,$A28,d_Modelo,$B28,d_Sector,J$6,d_Subest,$E$3,d_Tipo,$E$4) -> 115 | K28: =SUM(C28:J28) -> 174 | L28: =IF($K$71=0,0,K28/$K$71) -> 0.08877551
A29: SEL | B29: SEL | C29: =COUNTIFS(d_Marca,$A29,d_Modelo,$B29,d_Sector,C$6,d_Subest,$E$3,d_Tipo,$E$4) -> 0 | D29: =COUNTIFS(d_Marca,$A29,d_Modelo,$B29,d_Sector,D$6,d_Subest,$E$3,d_Tipo,$E$4) -> 0 | E29: =COUNTIFS(d_Marca,$A29,d_Modelo,$B29,d_Sector,E$6,d_Subest,$E$3,d_Tipo,$E$4) -> 26 | F29: =COUNTIFS(d_Marca,$A29,d_Modelo,$B29,d_Sector,F$6,d_Subest,$E$3,d_Tipo,$E$4) -> 50 | G29: =COUNTIFS(d_Marca,$A29,d_Modelo,$B29,d_Sector,G$6,d_Subest,$E$3,d_Tipo,$E$4) -> 51 | H29: =COUNTIFS(d_Marca,$A29,d_Modelo,$B29,d_Sector,H$6,d_Subest,$E$3,d_Tipo,$E$4) -> 0 | I29: =COUNTIFS(d_Marca,$A29,d_Modelo,$B29,d_Sector,I$6,d_Subest,$E$3,d_Tipo,$E$4) -> 6 | J29: =COUNTIFS(d_Marca,$A29,d_Modelo,$B29,d_Sector,J$6,d_Subest,$E$3,d_Tipo,$E$4) -> 0 | K29: =SUM(C29:J29) -> 133 | L29: =IF($K$71=0,0,K29/$K$71) -> 0.067857143
A30: SEL | B30: MEDICION | C30: =COUNTIFS(d_Marca,$A30,d_Modelo,$B30,d_Sector,C$6,d_Subest,$E$3,d_Tipo,$E$4) -> 0 | D30: =COUNTIFS(d_Marca,$A30,d_Modelo,$B30,d_Sector,D$6,d_Subest,$E$3,d_Tipo,$E$4) -> 20 | E30: =COUNTIFS(d_Marca,$A30,d_Modelo,$B30,d_Sector,E$6,d_Subest,$E$3,d_Tipo,$E$4) -> 0 | F30: =COUNTIFS(d_Marca,$A30,d_Modelo,$B30,d_Sector,F$6,d_Subest,$E$3,d_Tipo,$E$4) -> 0 | G30: =COUNTIFS(d_Marca,$A30,d_Modelo,$B30,d_Sector,G$6,d_Subest,$E$3,d_Tipo,$E$4) -> 0 | H30: =COUNTIFS(d_Marca,$A30,d_Modelo,$B30,d_Sector,H$6,d_Subest,$E$3,d_Tipo,$E$4) -> 0 | I30: =COUNTIFS(d_Marca,$A30,d_Modelo,$B30,d_Sector,I$6,d_Subest,$E$3,d_Tipo,$E$4) -> 0 | J30: =COUNTIFS(d_Marca,$A30,d_Modelo,$B30,d_Sector,J$6,d_Subest,$E$3,d_Tipo,$E$4) -> 0 | K30: =SUM(C30:J30) -> 20 | L30: =IF($K$71=0,0,K30/$K$71) -> 0.010204082
A31: SEL | B31: SEL-751 | C31: =COUNTIFS(d_Marca,$A31,d_Modelo,$B31,d_Sector,C$6,d_Subest,$E$3,d_Tipo,$E$4) -> 0 | D31: =COUNTIFS(d_Marca,$A31,d_Modelo,$B31,d_Sector,D$6,d_Subest,$E$3,d_Tipo,$E$4) -> 0 | E31: =COUNTIFS(d_Marca,$A31,d_Modelo,$B31,d_Sector,E$6,d_Subest,$E$3,d_Tipo,$E$4) -> 0 | F31: =COUNTIFS(d_Marca,$A31,d_Modelo,$B31,d_Sector,F$6,d_Subest,$E$3,d_Tipo,$E$4) -> 0 | G31: =COUNTIFS(d_Marca,$A31,d_Modelo,$B31,d_Sector,G$6,d_Subest,$E$3,d_Tipo,$E$4) -> 0 | H31: =COUNTIFS(d_Marca,$A31,d_Modelo,$B31,d_Sector,H$6,d_Subest,$E$3,d_Tipo,$E$4) -> 0 | I31: =COUNTIFS(d_Marca,$A31,d_Modelo,$B31,d_Sector,I$6,d_Subest,$E$3,d_Tipo,$E$4) -> 0 | J31: =COUNTIFS(d_Marca,$A31,d_Modelo,$B31,d_Sector,J$6,d_Subest,$E$3,d_Tipo,$E$4) -> 12 | K31: =SUM(C31:J31) -> 12 | L31: =IF($K$71=0,0,K31/$K$71) -> 0.006122449
A32: SEL | B32: SEL-411L | C32: =COUNTIFS(d_Marca,$A32,d_Modelo,$B32,d_Sector,C$6,d_Subest,$E$3,d_Tipo,$E$4) -> 0 | D32: =COUNTIFS(d_Marca,$A32,d_Modelo,$B32,d_Sector,D$6,d_Subest,$E$3,d_Tipo,$E$4) -> 0 | E32: =COUNTIFS(d_Marca,$A32,d_Modelo,$B32,d_Sector,E$6,d_Subest,$E$3,d_Tipo,$E$4) -> 0 | F32: =COUNTIFS(d_Marca,$A32,d_Modelo,$B32,d_Sector,F$6,d_Subest,$E$3,d_Tipo,$E$4) -> 0 | G32: =COUNTIFS(d_Marca,$A32,d_Modelo,$B32,d_Sector,G$6,d_Subest,$E$3,d_Tipo,$E$4) -> 0 | H32: =COUNTIFS(d_Marca,$A32,d_Modelo,$B32,d_Sector,H$6,d_Subest,$E$3,d_Tipo,$E$4) -> 0 | I32: =COUNTIFS(d_Marca,$A32,d_Modelo,$B32,d_Sector,I$6,d_Subest,$E$3,d_Tipo,$E$4) -> 0 | J32: =COUNTIFS(d_Marca,$A32,d_Modelo,$B32,d_Sector,J$6,d_Subest,$E$3,d_Tipo,$E$4) -> 4 | K32: =SUM(C32:J32) -> 4 | L32: =IF($K$71=0,0,K32/$K$71) -> 0.0020408163
A33: SEL | B33: 1AFFAEAGNEC5BNA11G | C33: =COUNTIFS(d_Marca,$A33,d_Modelo,$B33,d_Sector,C$6,d_Subest,$E$3,d_Tipo,$E$4) -> 2 | D33: =COUNTIFS(d_Marca,$A33,d_Modelo,$B33,d_Sector,D$6,d_Subest,$E$3,d_Tipo,$E$4) -> 0 | E33: =COUNTIFS(d_Marca,$A33,d_Modelo,$B33,d_Sector,E$6,d_Subest,$E$3,d_Tipo,$E$4) -> 0 | F33: =COUNTIFS(d_Marca,$A33,d_Modelo,$B33,d_Sector,F$6,d_Subest,$E$3,d_Tipo,$E$4) -> 0 | G33: =COUNTIFS(d_Marca,$A33,d_Modelo,$B33,d_Sector,G$6,d_Subest,$E$3,d_Tipo,$E$4) -> 0 | H33: =COUNTIFS(d_Marca,$A33,d_Modelo,$B33,d_Sector,H$6,d_Subest,$E$3,d_Tipo,$E$4) -> 0 | I33: =COUNTIFS(d_Marca,$A33,d_Modelo,$B33,d_Sector,I$6,d_Subest,$E$3,d_Tipo,$E$4) -> 0 | J33: =COUNTIFS(d_Marca,$A33,d_Modelo,$B33,d_Sector,J$6,d_Subest,$E$3,d_Tipo,$E$4) -> 0 | K33: =SUM(C33:J33) -> 2 | L33: =IF($K$71=0,0,K33/$K$71) -> 0.0010204082
A34: GENERAL ELECTRIC | B34: Total GENERAL ELECTRIC | C34: =COUNTIFS(d_Marca,$A34,d_Sector,C$6,d_Subest,$E$3,d_Tipo,$E$4) -> 0 | D34: =COUNTIFS(d_Marca,$A34,d_Sector,D$6,d_Subest,$E$3,d_Tipo,$E$4) -> 0 | E34: =COUNTIFS(d_Marca,$A34,d_Sector,E$6,d_Subest,$E$3,d_Tipo,$E$4) -> 48 | F34: =COUNTIFS(d_Marca,$A34,d_Sector,F$6,d_Subest,$E$3,d_Tipo,$E$4) -> 132 | G34: =COUNTIFS(d_Marca,$A34,d_Sector,G$6,d_Subest,$E$3,d_Tipo,$E$4) -> 104 | H34: =COUNTIFS(d_Marca,$A34,d_Sector,H$6,d_Subest,$E$3,d_Tipo,$E$4) -> 26 | I34: =COUNTIFS(d_Marca,$A34,d_Sector,I$6,d_Subest,$E$3,d_Tipo,$E$4) -> 2 | J34: =COUNTIFS(d_Marca,$A34,d_Sector,J$6,d_Subest,$E$3,d_Tipo,$E$4) -> 92 | K34: =SUM(C34:J34) -> 404 | L34: =IF($K$71=0,0,K34/$K$71) -> 0.20612245
A35: GENERAL ELECTRIC | B35: MULTILIN | C35: =COUNTIFS(d_Marca,$A35,d_Modelo,$B35,d_Sector,C$6,d_Subest,$E$3,d_Tipo,$E$4) -> 0 | D35: =COUNTIFS(d_Marca,$A35,d_Modelo,$B35,d_Sector,D$6,d_Subest,$E$3,d_Tipo,$E$4) -> 0 | E35: =COUNTIFS(d_Marca,$A35,d_Modelo,$B35,d_Sector,E$6,d_Subest,$E$3,d_Tipo,$E$4) -> 48 | F35: =COUNTIFS(d_Marca,$A35,d_Modelo,$B35,d_Sector,F$6,d_Subest,$E$3,d_Tipo,$E$4) -> 132 | G35: =COUNTIFS(d_Marca,$A35,d_Modelo,$B35,d_Sector,G$6,d_Subest,$E$3,d_Tipo,$E$4) -> 104 | H35: =COUNTIFS(d_Marca,$A35,d_Modelo,$B35,d_Sector,H$6,d_Subest,$E$3,d_Tipo,$E$4) -> 0 | I35: =COUNTIFS(d_Marca,$A35,d_Modelo,$B35,d_Sector,I$6,d_Subest,$E$3,d_Tipo,$E$4) -> 2 | J35: =COUNTIFS(d_Marca,$A35,d_Modelo,$B35,d_Sector,J$6,d_Subest,$E$3,d_Tipo,$E$4) -> 0 | K35: =SUM(C35:J35) -> 286 | L35: =IF($K$71=0,0,K35/$K$71) -> 0.14591837
A36: GENERAL ELECTRIC | B36: MULTILIN 350 | C36: =COUNTIFS(d_Marca,$A36,d_Modelo,$B36,d_Sector,C$6,d_Subest,$E$3,d_Tipo,$E$4) -> 0 | D36: =COUNTIFS(d_Marca,$A36,d_Modelo,$B36,d_Sector,D$6,d_Subest,$E$3,d_Tipo,$E$4) -> 0 | E36: =COUNTIFS(d_Marca,$A36,d_Modelo,$B36,d_Sector,E$6,d_Subest,$E$3,d_Tipo,$E$4) -> 0 | F36: =COUNTIFS(d_Marca,$A36,d_Modelo,$B36,d_Sector,F$6,d_Subest,$E$3,d_Tipo,$E$4) -> 0 | G36: =COUNTIFS(d_Marca,$A36,d_Modelo,$B36,d_Sector,G$6,d_Subest,$E$3,d_Tipo,$E$4) -> 0 | H36: =COUNTIFS(d_Marca,$A36,d_Modelo,$B36,d_Sector,H$6,d_Subest,$E$3,d_Tipo,$E$4) -> 26 | I36: =COUNTIFS(d_Marca,$A36,d_Modelo,$B36,d_Sector,I$6,d_Subest,$E$3,d_Tipo,$E$4) -> 0 | J36: =COUNTIFS(d_Marca,$A36,d_Modelo,$B36,d_Sector,J$6,d_Subest,$E$3,d_Tipo,$E$4) -> 8 | K36: =SUM(C36:J36) -> 34 | L36: =IF($K$71=0,0,K36/$K$71) -> 0.017346939
A37: GENERAL ELECTRIC | B37: MULTILIN T60 | C37: =COUNTIFS(d_Marca,$A37,d_Modelo,$B37,d_Sector,C$6,d_Subest,$E$3,d_Tipo,$E$4) -> 0 | D37: =COUNTIFS(d_Marca,$A37,d_Modelo,$B37,d_Sector,D$6,d_Subest,$E$3,d_Tipo,$E$4) -> 0 | E37: =COUNTIFS(d_Marca,$A37,d_Modelo,$B37,d_Sector,E$6,d_Subest,$E$3,d_Tipo,$E$4) -> 0 | F37: =COUNTIFS(d_Marca,$A37,d_Modelo,$B37,d_Sector,F$6,d_Subest,$E$3,d_Tipo,$E$4) -> 0 | G37: =COUNTIFS(d_Marca,$A37,d_Modelo,$B37,d_Sector,G$6,d_Subest,$E$3,d_Tipo,$E$4) -> 0 | H37: =COUNTIFS(d_Marca,$A37,d_Modelo,$B37,d_Sector,H$6,d_Subest,$E$3,d_Tipo,$E$4) -> 0 | I37: =COUNTIFS(d_Marca,$A37,d_Modelo,$B37,d_Sector,I$6,d_Subest,$E$3,d_Tipo,$E$4) -> 0 | J37: =COUNTIFS(d_Marca,$A37,d_Modelo,$B37,d_Sector,J$6,d_Subest,$E$3,d_Tipo,$E$4) -> 22 | K37: =SUM(C37:J37) -> 22 | L37: =IF($K$71=0,0,K37/$K$71) -> 0.01122449
A38: GENERAL ELECTRIC | B38: MULTILIN C30 | C38: =COUNTIFS(d_Marca,$A38,d_Modelo,$B38,d_Sector,C$6,d_Subest,$E$3,d_Tipo,$E$4) -> 0 | D38: =COUNTIFS(d_Marca,$A38,d_Modelo,$B38,d_Sector,D$6,d_Subest,$E$3,d_Tipo,$E$4) -> 0 | E38: =COUNTIFS(d_Marca,$A38,d_Modelo,$B38,d_Sector,E$6,d_Subest,$E$3,d_Tipo,$E$4) -> 0 | F38: =COUNTIFS(d_Marca,$A38,d_Modelo,$B38,d_Sector,F$6,d_Subest,$E$3,d_Tipo,$E$4) -> 0 | G38: =COUNTIFS(d_Marca,$A38,d_Modelo,$B38,d_Sector,G$6,d_Subest,$E$3,d_Tipo,$E$4) -> 0 | H38: =COUNTIFS(d_Marca,$A38,d_Modelo,$B38,d_Sector,H$6,d_Subest,$E$3,d_Tipo,$E$4) -> 0 | I38: =COUNTIFS(d_Marca,$A38,d_Modelo,$B38,d_Sector,I$6,d_Subest,$E$3,d_Tipo,$E$4) -> 0 | J38: =COUNTIFS(d_Marca,$A38,d_Modelo,$B38,d_Sector,J$6,d_Subest,$E$3,d_Tipo,$E$4) -> 21 | K38: =SUM(C38:J38) -> 21 | L38: =IF($K$71=0,0,K38/$K$71) -> 0.010714286
A39: GENERAL ELECTRIC | B39: MULTILIN F60 | C39: =COUNTIFS(d_Marca,$A39,d_Modelo,$B39,d_Sector,C$6,d_Subest,$E$3,d_Tipo,$E$4) -> 0 | D39: =COUNTIFS(d_Marca,$A39,d_Modelo,$B39,d_Sector,D$6,d_Subest,$E$3,d_Tipo,$E$4) -> 0 | E39: =COUNTIFS(d_Marca,$A39,d_Modelo,$B39,d_Sector,E$6,d_Subest,$E$3,d_Tipo,$E$4) -> 0 | F39: =COUNTIFS(d_Marca,$A39,d_Modelo,$B39,d_Sector,F$6,d_Subest,$E$3,d_Tipo,$E$4) -> 0 | G39: =COUNTIFS(d_Marca,$A39,d_Modelo,$B39,d_Sector,G$6,d_Subest,$E$3,d_Tipo,$E$4) -> 0 | H39: =COUNTIFS(d_Marca,$A39,d_Modelo,$B39,d_Sector,H$6,d_Subest,$E$3,d_Tipo,$E$4) -> 0 | I39: =COUNTIFS(d_Marca,$A39,d_Modelo,$B39,d_Sector,I$6,d_Subest,$E$3,d_Tipo,$E$4) -> 0 | J39: =COUNTIFS(d_Marca,$A39,d_Modelo,$B39,d_Sector,J$6,d_Subest,$E$3,d_Tipo,$E$4) -> 14 | K39: =SUM(C39:J39) -> 14 | L39: =IF($K$71=0,0,K39/$K$71) -> 0.0071428571
A40: GENERAL ELECTRIC | B40: MULTILIN B90 | C40: =COUNTIFS(d_Marca,$A40,d_Modelo,$B40,d_Sector,C$6,d_Subest,$E$3,d_Tipo,$E$4) -> 0 | D40: =COUNTIFS(d_Marca,$A40,d_Modelo,$B40,d_Sector,D$6,d_Subest,$E$3,d_Tipo,$E$4) -> 0 | E40: =COUNTIFS(d_Marca,$A40,d_Modelo,$B40,d_Sector,E$6,d_Subest,$E$3,d_Tipo,$E$4) -> 0 | F40: =COUNTIFS(d_Marca,$A40,d_Modelo,$B40,d_Sector,F$6,d_Subest,$E$3,d_Tipo,$E$4) -> 0 | G40: =COUNTIFS(d_Marca,$A40,d_Modelo,$B40,d_Sector,G$6,d_Subest,$E$3,d_Tipo,$E$4) -> 0 | H40: =COUNTIFS(d_Marca,$A40,d_Modelo,$B40,d_Sector,H$6,d_Subest,$E$3,d_Tipo,$E$4) -> 0 | I40: =COUNTIFS(d_Marca,$A40,d_Modelo,$B40,d_Sector,I$6,d_Subest,$E$3,d_Tipo,$E$4) -> 0 | J40: =COUNTIFS(d_Marca,$A40,d_Modelo,$B40,d_Sector,J$6,d_Subest,$E$3,d_Tipo,$E$4) -> 10 | K40: =SUM(C40:J40) -> 10 | L40: =IF($K$71=0,0,K40/$K$71) -> 0.0051020408
A41: GENERAL ELECTRIC | B41: MULTILIN G60 | C41: =COUNTIFS(d_Marca,$A41,d_Modelo,$B41,d_Sector,C$6,d_Subest,$E$3,d_Tipo,$E$4) -> 0 | D41: =COUNTIFS(d_Marca,$A41,d_Modelo,$B41,d_Sector,D$6,d_Subest,$E$3,d_Tipo,$E$4) -> 0 | E41: =COUNTIFS(d_Marca,$A41,d_Modelo,$B41,d_Sector,E$6,d_Subest,$E$3,d_Tipo,$E$4) -> 0 | F41: =COUNTIFS(d_Marca,$A41,d_Modelo,$B41,d_Sector,F$6,d_Subest,$E$3,d_Tipo,$E$4) -> 0 | G41: =COUNTIFS(d_Marca,$A41,d_Modelo,$B41,d_Sector,G$6,d_Subest,$E$3,d_Tipo,$E$4) -> 0 | H41: =COUNTIFS(d_Marca,$A41,d_Modelo,$B41,d_Sector,H$6,d_Subest,$E$3,d_Tipo,$E$4) -> 0 | I41: =COUNTIFS(d_Marca,$A41,d_Modelo,$B41,d_Sector,I$6,d_Subest,$E$3,d_Tipo,$E$4) -> 0 | J41: =COUNTIFS(d_Marca,$A41,d_Modelo,$B41,d_Sector,J$6,d_Subest,$E$3,d_Tipo,$E$4) -> 8 | K41: =SUM(C41:J41) -> 8 | L41: =IF($K$71=0,0,K41/$K$71) -> 0.0040816327
A42: GENERAL ELECTRIC | B42: MULTILIN L90 | C42: =COUNTIFS(d_Marca,$A42,d_Modelo,$B42,d_Sector,C$6,d_Subest,$E$3,d_Tipo,$E$4) -> 0 | D42: =COUNTIFS(d_Marca,$A42,d_Modelo,$B42,d_Sector,D$6,d_Subest,$E$3,d_Tipo,$E$4) -> 0 | E42: =COUNTIFS(d_Marca,$A42,d_Modelo,$B42,d_Sector,E$6,d_Subest,$E$3,d_Tipo,$E$4) -> 0 | F42: =COUNTIFS(d_Marca,$A42,d_Modelo,$B42,d_Sector,F$6,d_Subest,$E$3,d_Tipo,$E$4) -> 0 | G42: =COUNTIFS(d_Marca,$A42,d_Modelo,$B42,d_Sector,G$6,d_Subest,$E$3,d_Tipo,$E$4) -> 0 | H42: =COUNTIFS(d_Marca,$A42,d_Modelo,$B42,d_Sector,H$6,d_Subest,$E$3,d_Tipo,$E$4) -> 0 | I42: =COUNTIFS(d_Marca,$A42,d_Modelo,$B42,d_Sector,I$6,d_Subest,$E$3,d_Tipo,$E$4) -> 0 | J42: =COUNTIFS(d_Marca,$A42,d_Modelo,$B42,d_Sector,J$6,d_Subest,$E$3,d_Tipo,$E$4) -> 4 | K42: =SUM(C42:J42) -> 4 | L42: =IF($K$71=0,0,K42/$K$71) -> 0.0020408163
A43: GENERAL ELECTRIC | B43: MULTILIN T35 | C43: =COUNTIFS(d_Marca,$A43,d_Modelo,$B43,d_Sector,C$6,d_Subest,$E$3,d_Tipo,$E$4) -> 0 | D43: =COUNTIFS(d_Marca,$A43,d_Modelo,$B43,d_Sector,D$6,d_Subest,$E$3,d_Tipo,$E$4) -> 0 | E43: =COUNTIFS(d_Marca,$A43,d_Modelo,$B43,d_Sector,E$6,d_Subest,$E$3,d_Tipo,$E$4) -> 0 | F43: =COUNTIFS(d_Marca,$A43,d_Modelo,$B43,d_Sector,F$6,d_Subest,$E$3,d_Tipo,$E$4) -> 0 | G43: =COUNTIFS(d_Marca,$A43,d_Modelo,$B43,d_Sector,G$6,d_Subest,$E$3,d_Tipo,$E$4) -> 0 | H43: =COUNTIFS(d_Marca,$A43,d_Modelo,$B43,d_Sector,H$6,d_Subest,$E$3,d_Tipo,$E$4) -> 0 | I43: =COUNTIFS(d_Marca,$A43,d_Modelo,$B43,d_Sector,I$6,d_Subest,$E$3,d_Tipo,$E$4) -> 0 | J43: =COUNTIFS(d_Marca,$A43,d_Modelo,$B43,d_Sector,J$6,d_Subest,$E$3,d_Tipo,$E$4) -> 4 | K43: =SUM(C43:J43) -> 4 | L43: =IF($K$71=0,0,K43/$K$71) -> 0.0020408163
A44: GENERAL ELECTRIC | B44: MULTILIN 845 | C44: =COUNTIFS(d_Marca,$A44,d_Modelo,$B44,d_Sector,C$6,d_Subest,$E$3,d_Tipo,$E$4) -> 0 | D44: =COUNTIFS(d_Marca,$A44,d_Modelo,$B44,d_Sector,D$6,d_Subest,$E$3,d_Tipo,$E$4) -> 0 | E44: =COUNTIFS(d_Marca,$A44,d_Modelo,$B44,d_Sector,E$6,d_Subest,$E$3,d_Tipo,$E$4) -> 0 | F44: =COUNTIFS(d_Marca,$A44,d_Modelo,$B44,d_Sector,F$6,d_Subest,$E$3,d_Tipo,$E$4) -> 0 | G44: =COUNTIFS(d_Marca,$A44,d_Modelo,$B44,d_Sector,G$6,d_Subest,$E$3,d_Tipo,$E$4) -> 0 | H44: =COUNTIFS(d_Marca,$A44,d_Modelo,$B44,d_Sector,H$6,d_Subest,$E$3,d_Tipo,$E$4) -> 0 | I44: =COUNTIFS(d_Marca,$A44,d_Modelo,$B44,d_Sector,I$6,d_Subest,$E$3,d_Tipo,$E$4) -> 0 | J44: =COUNTIFS(d_Marca,$A44,d_Modelo,$B44,d_Sector,J$6,d_Subest,$E$3,d_Tipo,$E$4) -> 1 | K44: =SUM(C44:J44) -> 1 | L44: =IF($K$71=0,0,K44/$K$71) -> 0.00051020408
A45: SIEMENS | B45: Total SIEMENS | C45: =COUNTIFS(d_Marca,$A45,d_Sector,C$6,d_Subest,$E$3,d_Tipo,$E$4) -> 0 | D45: =COUNTIFS(d_Marca,$A45,d_Sector,D$6,d_Subest,$E$3,d_Tipo,$E$4) -> 0 | E45: =COUNTIFS(d_Marca,$A45,d_Sector,E$6,d_Subest,$E$3,d_Tipo,$E$4) -> 2 | F45: =COUNTIFS(d_Marca,$A45,d_Sector,F$6,d_Subest,$E$3,d_Tipo,$E$4) -> 6 | G45: =COUNTIFS(d_Marca,$A45,d_Sector,G$6,d_Subest,$E$3,d_Tipo,$E$4) -> 6 | H45: =COUNTIFS(d_Marca,$A45,d_Sector,H$6,d_Subest,$E$3,d_Tipo,$E$4) -> 0 | I45: =COUNTIFS(d_Marca,$A45,d_Sector,I$6,d_Subest,$E$3,d_Tipo,$E$4) -> 159 | J45: =COUNTIFS(d_Marca,$A45,d_Sector,J$6,d_Subest,$E$3,d_Tipo,$E$4) -> 109 | K45: =SUM(C45:J45) -> 282 | L45: =IF($K$71=0,0,K45/$K$71) -> 0.14387755
A46: SIEMENS | B46: REYROLLE | C46: =COUNTIFS(d_Marca,$A46,d_Modelo,$B46,d_Sector,C$6,d_Subest,$E$3,d_Tipo,$E$4) -> 0 | D46: =COUNTIFS(d_Marca,$A46,d_Modelo,$B46,d_Sector,D$6,d_Subest,$E$3,d_Tipo,$E$4) -> 0 | E46: =COUNTIFS(d_Marca,$A46,d_Modelo,$B46,d_Sector,E$6,d_Subest,$E$3,d_Tipo,$E$4) -> 0 | F46: =COUNTIFS(d_Marca,$A46,d_Modelo,$B46,d_Sector,F$6,d_Subest,$E$3,d_Tipo,$E$4) -> 6 | G46: =COUNTIFS(d_Marca,$A46,d_Modelo,$B46,d_Sector,G$6,d_Subest,$E$3,d_Tipo,$E$4) -> 0 | H46: =COUNTIFS(d_Marca,$A46,d_Modelo,$B46,d_Sector,H$6,d_Subest,$E$3,d_Tipo,$E$4) -> 0 | I46: =COUNTIFS(d_Marca,$A46,d_Modelo,$B46,d_Sector,I$6,d_Subest,$E$3,d_Tipo,$E$4) -> 129 | J46: =COUNTIFS(d_Marca,$A46,d_Modelo,$B46,d_Sector,J$6,d_Subest,$E$3,d_Tipo,$E$4) -> 0 | K46: =SUM(C46:J46) -> 135 | L46: =IF($K$71=0,0,K46/$K$71) -> 0.068877551
A47: SIEMENS | B47: 7SR5111 | C47: =COUNTIFS(d_Marca,$A47,d_Modelo,$B47,d_Sector,C$6,d_Subest,$E$3,d_Tipo,$E$4) -> 0 | D47: =COUNTIFS(d_Marca,$A47,d_Modelo,$B47,d_Sector,D$6,d_Subest,$E$3,d_Tipo,$E$4) -> 0 | E47: =COUNTIFS(d_Marca,$A47,d_Modelo,$B47,d_Sector,E$6,d_Subest,$E$3,d_Tipo,$E$4) -> 0 | F47: =COUNTIFS(d_Marca,$A47,d_Modelo,$B47,d_Sector,F$6,d_Subest,$E$3,d_Tipo,$E$4) -> 0 | G47: =COUNTIFS(d_Marca,$A47,d_Modelo,$B47,d_Sector,G$6,d_Subest,$E$3,d_Tipo,$E$4) -> 0 | H47: =COUNTIFS(d_Marca,$A47,d_Modelo,$B47,d_Sector,H$6,d_Subest,$E$3,d_Tipo,$E$4) -> 0 | I47: =COUNTIFS(d_Marca,$A47,d_Modelo,$B47,d_Sector,I$6,d_Subest,$E$3,d_Tipo,$E$4) -> 0 | J47: =COUNTIFS(d_Marca,$A47,d_Modelo,$B47,d_Sector,J$6,d_Subest,$E$3,d_Tipo,$E$4) -> 45 | K47: =SUM(C47:J47) -> 45 | L47: =IF($K$71=0,0,K47/$K$71) -> 0.022959184
...

Sheet Pivot_Subestacion
A1: TABLA DINÁMICA · RELEVADORES POR SUBESTACIÓN Y MARCA
A2: Subestaciones eléctricas (ubicaciones técnicas "SEL") ordenadas por sector. Los relevadores en áreas de proceso se agrupan en la última fila.
A3: Sector (filtro) | B3: (Todos) | D3: criterio: | E3: =IF($B$3="(Todos)","*",$B$3) -> *
A5: Sector | B5: Subestación | C5: Planta / descripción | D5: ABB | E5: SEL | F5: GENERAL ELECTRIC | G5: SIEMENS | H5: SCHNEIDER ELECTRIC | I5: ALLEN-BRADLEY | J5: BASLER ELECTRIC | K5: EIG | L5: GAUGETECH | M5: SIN DATO | N5: Total | O5: % del total
A6: Sector 1 | B6: SE-12 | C6: U-DE DESTILACIÓN COMBINADA (UDC2) TREN 2 | D6: =COUNTIFS(d_Subest,$B6,d_Marca,D$5,d_Sector,$E$3) -> 61 | E6: =COUNTIFS(d_Subest,$B6,d_Marca,E$5,d_Sector,$E$3) -> 7 | F6: =COUNTIFS(d_Subest,$B6,d_Marca,F$5,d_Sector,$E$3) -> 0 | G6: =COUNTIFS(d_Subest,$B6,d_Marca,G$5,d_Sector,$E$3) -> 0 | H6: =COUNTIFS(d_Subest,$B6,d_Marca,H$5,d_Sector,$E$3) -> 0 | I6: =COUNTIFS(d_Subest,$B6,d_Marca,I$5,d_Sector,$E$3) -> 0 | J6: =COUNTIFS(d_Subest,$B6,d_Marca,J$5,d_Sector,$E$3) -> 0 | K6: =COUNTIFS(d_Subest,$B6,d_Marca,K$5,d_Sector,$E$3) -> 0 | ... M6: =COUNTIFS(d_Subest,$B6,d_Marca,M$5,d_Sector,$E$3) -> 0 | N6: =SUM(D6:M6) -> 68 | O6: =IF($N$47=0,0,N6/$N$47) -> 0.034693878
A7: Sector 1 | B7: SE-12-1 | C7: U-DE DESTILACIÓN COMBINADA (UDC1) TREN 1 | D7: =COUNTIFS(d_Subest,$B7,d_Marca,D$5,d_Sector,$E$3) -> 50 | E7: =COUNTIFS(d_Subest,$B7,d_Marca,E$5,d_Sector,$E$3) -> 3 | F7: =COUNTIFS(d_Subest,$B7,d_Marca,F$5,d_Sector,$E$3) -> 0 | G7: =COUNTIFS(d_Subest,$B7,d_Marca,G$5,d_Sector,$E$3) -> 0 | H7: =COUNTIFS(d_Subest,$B7,d_Marca,H$5,d_Sector,$E$3) -> 0 | I7: =COUNTIFS(d_Subest,$B7,d_Marca,I$5,d_Sector,$E$3) -> 0 | J7: =COUNTIFS(d_Subest,$B7,d_Marca,J$5,d_Sector,$E$3) -> 0 | K7: =COUNTIFS(d_Subest,$B7,d_Marca,K$5,d_Sector,$E$3) -> 0 | ... M7: =COUNTIFS(d_Subest,$B7,d_Marca,M$5,d_Sector,$E$3) -> 0 | N7: =SUM(D7:M7) -> 53 | O7: =IF($N$47=0,0,N7/$N$47) -> 0.027040816
A8: Sector 2 | B8: SE-15 | C8: U-DE COQUIZACIÓN RETARDADA | D8: =COUNTIFS(d_Subest,$B8,d_Marca,D$5,d_Sector,$E$3) -> 42 | E8: =COUNTIFS(d_Subest,$B8,d_Marca,E$5,d_Sector,$E$3) -> 4 | F8: =COUNTIFS(d_Subest,$B8,d_Marca,F$5,d_Sector,$E$3) -> 0 | G8: =COUNTIFS(d_Subest,$B8,d_Marca,G$5,d_Sector,$E$3) -> 0 | H8: =COUNTIFS(d_Subest,$B8,d_Marca,H$5,d_Sector,$E$3) -> 0 | I8: =COUNTIFS(d_Subest,$B8,d_Marca,I$5,d_Sector,$E$3) -> 0 | J8: =COUNTIFS(d_Subest,$B8,d_Marca,J$5,d_Sector,$E$3) -> 0 | K8: =COUNTIFS(d_Subest,$B8,d_Marca,K$5,d_Sector,$E$3) -> 0 | ... M8: =COUNTIFS(d_Subest,$B8,d_Marca,M$5,d_Sector,$E$3) -> 0 | N8: =SUM(D8:M8) -> 46 | O8: =IF($N$47=0,0,N8/$N$47) -> 0.023469388
A9: Sector 2 | B9: SE-15-1 | C9: U-DE COQUIZACIÓN RETARDADA | D9: =COUNTIFS(d_Subest,$B9,d_Marca,D$5,d_Sector,$E$3) -> 26 | E9: =COUNTIFS(d_Subest,$B9,d_Marca,E$5,d_Sector,$E$3) -> 12 | F9: =COUNTIFS(d_Subest,$B9,d_Marca,F$5,d_Sector,$E$3) -> 0 | G9: =COUNTIFS(d_Subest,$B9,d_Marca,G$5,d_Sector,$E$3) -> 0 | H9: =COUNTIFS(d_Subest,$B9,d_Marca,H$5,d_Sector,$E$3) -> 0 | I9: =COUNTIFS(d_Subest,$B9,d_Marca,I$5,d_Sector,$E$3) -> 0 | J9: =COUNTIFS(d_Subest,$B9,d_Marca,J$5,d_Sector,$E$3) -> 0 | K9: =COUNTIFS(d_Subest,$B9,d_Marca,K$5,d_Sector,$E$3) -> 0 | ... M9: =COUNTIFS(d_Subest,$B9,d_Marca,M$5,d_Sector,$E$3) -> 0 | N9: =SUM(D9:M9) -> 38 | O9: =IF($N$47=0,0,N9/$N$47) -> 0.019387755
A10: Sector 3 | B10: SE-07 | C10: PLANTA DESINTEGRACIÓN CATALÍTICA (FCC1) | D10: =COUNTIFS(d_Subest,$B10,d_Marca,D$5,d_Sector,$E$3) -> 0 | E10: =COUNTIFS(d_Subest,$B10,d_Marca,E$5,d_Sector,$E$3) -> 16 | F10: =COUNTIFS(d_Subest,$B10,d_Marca,F$5,d_Sector,$E$3) -> 27 | G10: =COUNTIFS(d_Subest,$B10,d_Marca,G$5,d_Sector,$E$3) -> 2 | H10: =COUNTIFS(d_Subest,$B10,d_Marca,H$5,d_Sector,$E$3) -> 0 | I10: =COUNTIFS(d_Subest,$B10,d_Marca,I$5,d_Sector,$E$3) -> 0 | J10: =COUNTIFS(d_Subest,$B10,d_Marca,J$5,d_Sector,$E$3) -> 0 | K10: =COUNTIFS(d_Subest,$B10,d_Marca,K$5,d_Sector,$E$3) -> 0 | ... M10: =COUNTIFS(d_Subest,$B10,d_Marca,M$5,d_Sector,$E$3) -> 0 | N10: =SUM(D10:M10) -> 45 | O10: =IF($N$47=0,0,N10/$N$47) -> 0.022959184
A11: Sector 3 | B11: SE-14 | C11: U-DE ALQUILACIÓN (ALKY1) | D11: =COUNTIFS(d_Subest,$B11,d_Marca,D$5,d_Sector,$E$3) -> 39 | E11: =COUNTIFS(d_Subest,$B11,d_Marca,E$5,d_Sector,$E$3) -> 10 | F11: =COUNTIFS(d_Subest,$B11,d_Marca,F$5,d_Sector,$E$3) -> 0 | G11: =COUNTIFS(d_Subest,$B11,d_Marca,G$5,d_Sector,$E$3) -> 0 | H11: =COUNTIFS(d_Subest,$B11,d_Marca,H$5,d_Sector,$E$3) -> 0 | I11: =COUNTIFS(d_Subest,$B11,d_Marca,I$5,d_Sector,$E$3) -> 0 | J11: =COUNTIFS(d_Subest,$B11,d_Marca,J$5,d_Sector,$E$3) -> 0 | K11: =COUNTIFS(d_Subest,$B11,d_Marca,K$5,d_Sector,$E$3) -> 0 | ... M11: =COUNTIFS(d_Subest,$B11,d_Marca,M$5,d_Sector,$E$3) -> 0 | N11: =SUM(D11:M11) -> 49 | O11: =IF($N$47=0,0,N11/$N$47) -> 0.025
A12: Sector 4 | B12: SE-23 | C12: U-GENERADORA DE HIDRÓGENO (PH21) TREN 1 | D12: =COUNTIFS(d_Subest,$B12,d_Marca,D$5,d_Sector,$E$3) -> 18 | E12: =COUNTIFS(d_Subest,$B12,d_Marca,E$5,d_Sector,$E$3) -> 14 | F12: =COUNTIFS(d_Subest,$B12,d_Marca,F$5,d_Sector,$E$3) -> 0 | G12: =COUNTIFS(d_Subest,$B12,d_Marca,G$5,d_Sector,$E$3) -> 0 | H12: =COUNTIFS(d_Subest,$B12,d_Marca,H$5,d_Sector,$E$3) -> 0 | I12: =COUNTIFS(d_Subest,$B12,d_Marca,I$5,d_Sector,$E$3) -> 0 | J12: =COUNTIFS(d_Subest,$B12,d_Marca,J$5,d_Sector,$E$3) -> 0 | K12: =COUNTIFS(d_Subest,$B12,d_Marca,K$5,d_Sector,$E$3) -> 0 | ... M12: =COUNTIFS(d_Subest,$B12,d_Marca,M$5,d_Sector,$E$3) -> 0 | N12: =SUM(D12:M12) -> 32 | O12: =IF($N$47=0,0,N12/$N$47) -> 0.016326531
A13: Sector 4 | B13: SE-24 | C13: U-HIDROTRAT DE GASÓLEOS (HDTGO) NÚM. 1 | D13: =COUNTIFS(d_Subest,$B13,d_Marca,D$5,d_Sector,$E$3) -> 0 | E13: =COUNTIFS(d_Subest,$B13,d_Marca,E$5,d_Sector,$E$3) -> 12 | F13: =COUNTIFS(d_Subest,$B13,d_Marca,F$5,d_Sector,$E$3) -> 24 | G13: =COUNTIFS(d_Subest,$B13,d_Marca,G$5,d_Sector,$E$3) -> 2 | H13: =COUNTIFS(d_Subest,$B13,d_Marca,H$5,d_Sector,$E$3) -> 0 | I13: =COUNTIFS(d_Subest,$B13,d_Marca,I$5,d_Sector,$E$3) -> 0 | J13: =COUNTIFS(d_Subest,$B13,d_Marca,J$5,d_Sector,$E$3) -> 0 | K13: =COUNTIFS(d_Subest,$B13,d_Marca,K$5,d_Sector,$E$3) -> 0 | ... M13: =COUNTIFS(d_Subest,$B13,d_Marca,M$5,d_Sector,$E$3) -> 0 | N13: =SUM(D13:M13) -> 38 | O13: =IF($N$47=0,0,N13/$N$47) -> 0.019387755
A14: Sector 4 | B14: SE-26 | C14: U-HIDROTRAT DESTILADOS INTER (HDDI1) T-1 | D14: =COUNTIFS(d_Subest,$B14,d_Marca,D$5,d_Sector,$E$3) -> 0 | E14: =COUNTIFS(d_Subest,$B14,d_Marca,E$5,d_Sector,$E$3) -> 12 | F14: =COUNTIFS(d_Subest,$B14,d_Marca,F$5,d_Sector,$E$3) -> 20 | G14: =COUNTIFS(d_Subest,$B14,d_Marca,G$5,d_Sector,$E$3) -> 2 | H14: =COUNTIFS(d_Subest,$B14,d_Marca,H$5,d_Sector,$E$3) -> 0 | I14: =COUNTIFS(d_Subest,$B14,d_Marca,I$5,d_Sector,$E$3) -> 0 | J14: =COUNTIFS(d_Subest,$B14,d_Marca,J$5,d_Sector,$E$3) -> 0 | K14: =COUNTIFS(d_Subest,$B14,d_Marca,K$5,d_Sector,$E$3) -> 0 | ... M14: =COUNTIFS(d_Subest,$B14,d_Marca,M$5,d_Sector,$E$3) -> 0 | N14: =SUM(D14:M14) -> 34 | O14: =IF($N$47=0,0,N14/$N$47) -> 0.017346939
A15: Sector 4 | B15: SE-27 | C15: U-HIDROTRAT DESTILADOS INTER (HDDI2) T-2 | D15: =COUNTIFS(d_Subest,$B15,d_Marca,D$5,d_Sector,$E$3) -> 0 | E15: =COUNTIFS(d_Subest,$B15,d_Marca,E$5,d_Sector,$E$3) -> 12 | F15: =COUNTIFS(d_Subest,$B15,d_Marca,F$5,d_Sector,$E$3) -> 20 | G15: =COUNTIFS(d_Subest,$B15,d_Marca,G$5,d_Sector,$E$3) -> 2 | H15: =COUNTIFS(d_Subest,$B15,d_Marca,H$5,d_Sector,$E$3) -> 0 | I15: =COUNTIFS(d_Subest,$B15,d_Marca,I$5,d_Sector,$E$3) -> 0 | J15: =COUNTIFS(d_Subest,$B15,d_Marca,J$5,d_Sector,$E$3) -> 0 | K15: =COUNTIFS(d_Subest,$B15,d_Marca,K$5,d_Sector,$E$3) -> 0 | ... M15: =COUNTIFS(d_Subest,$B15,d_Marca,M$5,d_Sector,$E$3) -> 0 | N15: =SUM(D15:M15) -> 34 | O15: =IF($N$47=0,0,N15/$N$47) -> 0.017346939
A16: Sector 5 | B16: SE-03 | C16: U-HIDROTRAT DE NAFTAS (HDN1) TREN 1 | D16: =COUNTIFS(d_Subest,$B16,d_Marca,D$5,d_Sector,$E$3) -> 0 | E16: =COUNTIFS(d_Subest,$B16,d_Marca,E$5,d_Sector,$E$3) -> 12 | F16: =COUNTIFS(d_Subest,$B16,d_Marca,F$5,d_Sector,$E$3) -> 20 | G16: =COUNTIFS(d_Subest,$B16,d_Marca,G$5,d_Sector,$E$3) -> 2 | H16: =COUNTIFS(d_Subest,$B16,d_Marca,H$5,d_Sector,$E$3) -> 0 | I16: =COUNTIFS(d_Subest,$B16,d_Marca,I$5,d_Sector,$E$3) -> 0 | J16: =COUNTIFS(d_Subest,$B16,d_Marca,J$5,d_Sector,$E$3) -> 0 | K16: =COUNTIFS(d_Subest,$B16,d_Marca,K$5,d_Sector,$E$3) -> 0 | ... M16: =COUNTIFS(d_Subest,$B16,d_Marca,M$5,d_Sector,$E$3) -> 0 | N16: =SUM(D16:M16) -> 34 | O16: =IF($N$47=0,0,N16/$N$47) -> 0.017346939
A17: Sector 5 | B17: SE-04 | C17: U-HIDROTRAT DE NAFTAS (HDN2) TREN 2 | D17: =COUNTIFS(d_Subest,$B17,d_Marca,D$5,d_Sector,$E$3) -> 0 | E17: =COUNTIFS(d_Subest,$B17,d_Marca,E$5,d_Sector,$E$3) -> 12 | F17: =COUNTIFS(d_Subest,$B17,d_Marca,F$5,d_Sector,$E$3) -> 20 | G17: =COUNTIFS(d_Subest,$B17,d_Marca,G$5,d_Sector,$E$3) -> 2 | H17: =COUNTIFS(d_Subest,$B17,d_Marca,H$5,d_Sector,$E$3) -> 0 | I17: =COUNTIFS(d_Subest,$B17,d_Marca,I$5,d_Sector,$E$3) -> 0 | J17: =COUNTIFS(d_Subest,$B17,d_Marca,J$5,d_Sector,$E$3) -> 0 | K17: =COUNTIFS(d_Subest,$B17,d_Marca,K$5,d_Sector,$E$3) -> 0 | ... M17: =COUNTIFS(d_Subest,$B17,d_Marca,M$5,d_Sector,$E$3) -> 0 | N17: =SUM(D17:M17) -> 34 | O17: =IF($N$47=0,0,N17/$N$47) -> 0.017346939
... A46: — | B46: ÁREA DE PROCESO | C46: Relevadores en áreas de proceso (sin subestación asignada) | D46: =COUNTIFS(d_Subest,$B46,d_Marca,D$5,d_Sector,$E$3) -> 255 | E46: =COUNTIFS(d_Subest,$B46,d_Marca,E$5,d_Sector,$E$3) -> 23 | F46: =COUNTIFS(d_Subest,$B46,d_Marca,F$5,d_Sector,$E$3) -> 147 | G46: =COUNTIFS(d_Subest,$B46,d_Marca,G$5,d_Sector,$E$3) -> 100 | H46: =COUNTIFS(d_Subest,$B46,d_Marca,H$5,d_Sector,$E$3) -> 0 | I46: =COUNTIFS(d_Subest,$B46,d_Marca,I$5,d_Sector,$E$3) -> 8 | J46: =COUNTIFS(d_Subest,$B46,d_Marca,J$5,d_Sector,$E$3) -> 0 | K46: =COUNTIFS(d_Subest,$B46,d_Marca,K$5,d_Sector,$E$3) -> 0 | ... M46: =COUNTIFS(d_Subest,$B46,d_Marca,M$5,d_Sector,$E$3) -> 11 | N46: =SUM(D46:M46) -> 544 | O46: =IF($N$47=0,0,N46/$N$47) -> 0.27755102
A47: TOTAL | D47: =SUM(D6:D46) -> 816 | E47: =SUM(E6:E46) -> 345 | F47: =SUM(F6:F46) -> 404 | G47: =SUM(G6:G46) -> 282 | H47: =SUM(H6:H46) -> 40 | I47: =SUM(I6:I46) -> 8 | J47: =SUM(J6:J46) -> 6 | K47: =SUM(K6:K46) -> 2 | ... N47: =SUM(N6:N46) -> 1960 | O47: =IF($N$47=0,0,N47/$N$47) -> 1

Sheet Pivot_Mod_Subest
A1: TABLA DINÁMICA · RELEVADORES POR MARCA Y MODELO × SUBESTACIÓN (AGRUPADO POR SECTOR)
A2: Cada columna es una subestación; al final de cada sector va su subtotal. Use el filtro de la columna A para ver una sola marca.
A6: Marca | B6: Modelo | C6: Sector 1 | D6: Sector 1 | E6: Sector 1 | F6: Sector 2 | G6: Sector 2 | H6: Sector 2 | I6: Sector 3 | J6: Sector 3 | K6: Sector 3 | L6: Sector 4 | M6: Sector 4 | N6: Sector 4 | O6: Sector 4 | P6: Sector 4 | Q6: Sector 5 | R6: Sector 5 | S6: Sector 5 | T6: Sector 5 | U6: Sector 5 | V6: Sector 5 | W6: Sector 6 | X6: Sector 6 | Y6: Sector 6 | Z6: Sector 6 | AA6: Sector 6 | AB6: Sector 6 | AC6: Sector 7 | AD6: Sector 7 | AE6: Sector 7 | AF6: Sector 7 | AG6: Sector 7 | AH6: Sector 7 | AI6: Sector 7 | AJ6: Sector 7 | AK6: Sector 7 | AL6: Sector 7 | AM6: Sector 7 | AN6: Sector 8 | AO6: Sector 8 | AP6: Sector 8 | AQ6: Sector 8 | AR6: Sector 8 | AS6: Sector 8 | AT6: Sector 8 | AU6: Sector 8 | AV6: Sector 8 | AW6: Sector 8 | AX6: Sector 8 | AY6: Sin subestación | AZ6: TOTAL
A7: Sector → | C7: SE-12 | D7: SE-12-1 | E7: Total Sector 1 | F7: SE-15 | G7: SE-15-1 | H7: Total Sector 2 | I7: SE-07 | J7: SE-14 | K7: Total Sector 3 | L7: SE-23 | M7: SE-24 | N7: SE-26 | O7: SE-27 | P7: Total Sector 4 | Q7: SE-03 | R7: SE-04 | S7: SE-05 | T7: SE-06 | U7: SE-11 | V7: Total Sector 5 | W7: SE-02 | X7: SE-08 | Y7: SE-09 | Z7: SE-28 | AA7: SE-29 | AB7: Total Sector 6 | AC7: CE-19-1 | AD7: SE-10 | AE7: SE-13 | AF7: SE-19-1 | AG7: SE-20 | AH7: SE-20-1 | AI7: SE-21 | AJ7: SE-21-1 | AK7: SE-22 | AL7: SE-33 | AM7: Total Sector 7 | AN7: SE-01 | AO7: SE-16 | AP7: SE-17 | AQ7: SE-18 | AR7: SE-18-1 | AS7: SE-19 | AT7: SE-25 | AU7: SE-30 | AV7: SEP-01 | AW7: SEP-02 | AX7: Total Sector 8 | AY7: ÁREA DE PROCESO | AZ7: TOTAL GENERAL
A8: Subestación → | C8: U-DE DESTILACIÓN COMBINADA (UDC2) TREN 2 | D8: U-DE DESTILACIÓN COMBINADA (UDC1) TREN 1 | F8: U-DE COQUIZACIÓN RETARDADA | G8: U-DE COQUIZACIÓN RETARDADA | I8: PLANTA DESINTEGRACIÓN CATALÍTICA (FCC1) | J8: U-DE ALQUILACIÓN (ALKY1) | L8: U-GENERADORA DE HIDRÓGENO (PH21) TREN 1 | M8: U-HIDROTRAT DE GASÓLEOS (HDTGO) NÚM. 1 | N8: U-HIDROTRAT DESTILADOS INTER (HDDI1) T-1 | O8: U-HIDROTRAT DESTILADOS INTER (HDDI2) T-2 | Q8: U-HIDROTRAT DE NAFTAS (HDN1) TREN 1 | R8: U-HIDROTRAT DE NAFTAS (HDN2) TREN 2 | S8: U-TRATAMIENTO/RECUPERACIÓN GAS (PTRG1) | T8: U-ISOMERIZADORA PENTANOS/HEXANOS (PNX1) | U8: U-REFORMADORA CATALÍTICA NAFTAS (REF1) | W8: U-RECUPERADORA DE AZUFRE (PRA1) TREN 1 | X8: PLANTA DE TTO DE AGUAS AMARGAS COMUN | Y8: U-DE TRATAMIENTO DE AMINA AREA COMUN | Z8: EDIFICIO ADMINISTRATIVO NORTE | AA8: EDIFICIO ADMINISTRATIVO SUR | AC8: DESFOGUE DE QUEMADOR DE GASES | AD8: PLANTA DE TRATAMIENTO DE EFLUENTES | AE8: CARCAMO NORTE | AF8: CASA DE BOMBAS 5 | AG8: CASA DE BOMBAS 1 | AH8: CARCAMO OCCIDENTE | AI8: CASA DE BOMBAS 2 | AJ8: CASA DE BOMBAS 3 | AK8: CASA DE BOMBAS 4 | AL8: CARCAMO SUR | AN8: UNIDAD DESMINERALIZADORA DE AGUA | AO8: SECCION TORRE DE ENFRIAMIENTO CT-00201 | AP8: SERVICIOS COMPLEMENTARIOS | AQ8: SECCION DE CONTRAINCENDIO | AR8: PRETRATAMIENTO DE AGUA | AS8: SECCION TORRE DE ENFRIAMIENTO CT-00202 | AT8: SECCION TORRE DE ENFRIAMIENTO CT-00203 | AU8: SUMINISTRO DE AGUA CRUDA | AV8: PLANTA DE COGENERACIÓN | AW8: PLANTA DE COGENERACIÓN
A9: ABB | B9: Total ABB | C9: =COUNTIFS(d_Marca,$A9,d_Subest,C$7) -> 61 | D9: =COUNTIFS(d_Marca,$A9,d_Subest,D$7) -> 50 | E9: =SUM(C9:D9) -> 111 | F9: =COUNTIFS(d_Marca,$A9,d_Subest,F$7) -> 42 | G9: =COUNTIFS(d_Marca,$A9,d_Subest,G$7) -> 26 | H9: =SUM(F9:G9) -> 68 | I9: =COUNTIFS(d_Marca,$A9,d_Subest,I$7) -> 0 | J9: =COUNTIFS(d_Marca,$A9,d_Subest,J$7) -> 39 | K9: =SUM(I9:J9) -> 39 | L9: =COUNTIFS(d_Marca,$A9,d_Subest,L$7) -> 18 | M9: =COUNTIFS(d_Marca,$A9,d_Subest,M$7) -> 0 | N9: =COUNTIFS(d_Marca,$A9,d_Subest,N$7) -> 0 | O9: =COUNTIFS(d_Marca,$A9,d_Subest,O$7) -> 0 | P9: =SUM(L9:O9) -> 18 | Q9: =COUNTIFS(d_Marca,$A9,d_Subest,Q$7) -> 0 | R9: =COUNTIFS(d_Marca,$A9,d_Subest,R$7) -> 0 | S9: =COUNTIFS(d_Marca,$A9,d_Subest,S$7) -> 0 | T9: =COUNTIFS(d_Marca,$A9,d_Subest,T$7) -> 30 | U9: =COUNTIFS(d_Marca,$A9,d_Subest,U$7) -> 0 | V9: =SUM(Q9:U9) -> 30 | W9: =COUNTIFS(d_Marca,$A9,d_Subest,W$7) -> 24 | X9: =COUNTIFS(d_Marca,$A9,d_Subest,X$7) -> 25 | Y9: =COUNTIFS(d_Marca,$A9,d_Subest,Y$7) -> 21 | Z9: =COUNTIFS(d_Marca,$A9,d_Subest,Z$7) -> 22 | AA9: =COUNTIFS(d_Marca,$A9,d_Subest,AA$7) -> 24 | AB9: =SUM(W9:AA9) -> 116 | AC9: =COUNTIFS(d_Marca,$A9,d_Subest,AC$7) -> 0 | AD9: =COUNTIFS(d_Marca,$A9,d_Subest,AD$7) -> 0 | AE9: =COUNTIFS(d_Marca,$A9,d_Subest,AE$7) -> 0 | AF9: =COUNTIFS(d_Marca,$A9,d_Subest,AF$7) -> 4 | AG9: =COUNTIFS(d_Marca,$A9,d_Subest,AG$7) -> 0 | AH9: =COUNTIFS(d_Marca,$A9,d_Subest,AH$7) -> 0 | AI9: =COUNTIFS(d_Marca,$A9,d_Subest,AI$7) -> 0 | AJ9: =COUNTIFS(d_Marca,$A9,d_Subest,AJ$7) -> 0 | ... AL9: =COUNTIFS(d_Marca,$A9,d_Subest,AL$7) -> 0 | AM9: =SUM(AC9:AL9) -> 4 | AN9: =COUNTIFS(d_Marca,$A9,d_Subest,AN$7) -> 0 | AO9: =COUNTIFS(d_Marca,$A9,d_Subest,AO$7) -> 22 | AP9: =COUNTIFS(d_Marca,$A9,d_Subest,AP$7) -> 0 | AQ9: =COUNTIFS(d_Marca,$A9,d_Subest,AQ$7) -> 0 | AR9: =COUNTIFS(d_Marca,$A9,d_Subest,AR$7) -> 0 | AS9: =COUNTIFS(d_Marca,$A9,d_Subest,AS$7) -> 28 | AT9: =COUNTIFS(d_Marca,$A9,d_Subest,AT$7) -> 0 | AU9: =COUNTIFS(d_Marca,$A9,d_Subest,AU$7) -> 0 | ... AW9: =COUNTIFS(d_Marca,$A9,d_Subest,AW$7) -> 63 | AX9: =SUM(AN9:AW9) -> 175 | AY9: =COUNTIFS(d_Marca,$A9,d_Subest,AY$7) -> 255 | AZ9: =E9+H9+K9+P9+V9+AB9+AM9+AX9+AY9 -> 816
A10: ABB | B10: 1AFFAEAGNEC5BNA11G | C10: =COUNTIFS(d_Marca,$A10,d_Modelo,$B10,d_Subest,C$7) -> 46 | D10: =COUNTIFS(d_Marca,$A10,d_Modelo,$B10,d_Subest,D$7) -> 35 | E10: =SUM(C10:D10) -> 81 | F10: =COUNTIFS(d_Marca,$A10,d_Modelo,$B10,d_Subest,F$7) -> 11 | G10: =COUNTIFS(d_Marca,$A10,d_Modelo,$B10,d_Subest,G$7) -> 13 | H10: =SUM(F10:G10) -> 24 | I10: =COUNTIFS(d_Marca,$A10,d_Modelo,$B10,d_Subest,I$7) -> 0 | J10: =COUNTIFS(d_Marca,$A10,d_Modelo,$B10,d_Subest,J$7) -> 0 | K10: =SUM(I10:J10) -> 0 | L10: =COUNTIFS(d_Marca,$A10,d_Modelo,$B10,d_Subest,L$7) -> 0 | M10: =COUNTIFS(d_Marca,$A10,d_Modelo,$B10,d_Subest,M$7) -> 0 | N10: =COUNTIFS(d_Marca,$A10,d_Modelo,$B10,d_Subest,N$7) -> 0 | O10: =COUNTIFS(d_Marca,$A10,d_Modelo,$B10,d_Subest,O$7) -> 0 | P10: =SUM(L10:O10) -> 0 | Q10: =COUNTIFS(d_Marca,$A10,d_Modelo,$B10,d_Subest,Q$7) -> 0 | R10: =COUNTIFS(d_Marca,$A10,d_Modelo,$B10,d_Subest,R$7) -> 0 | S10: =COUNTIFS(d_Marca,$A10,d_Modelo,$B10,d_Subest,S$7) -> 0 | T10: =COUNTIFS(d_Marca,$A10,d_Modelo,$B10,d_Subest,T$7) -> 0 | U10: =COUNTIFS(d_Marca,$A10,d_Modelo,$B10,d_Subest,U$7) -> 0 | V10: =SUM(Q10:U10) -> 0 | W10: =COUNTIFS(d_Marca,$A10,d_Modelo,$B10,d_Subest,W$7) -> 0 | X10: =COUNTIFS(d_Marca,$A10,d_Modelo,$B10,d_Subest,X$7) -> 0 | Y10: =COUNTIFS(d_Marca,$A10,d_Modelo,$B10,d_Subest,Y$7) -> 0 | Z10: =COUNTIFS(d_Marca,$A10,d_Modelo,$B10,d_Subest,Z$7) -> 0 | AA10: =COUNTIFS(d_Marca,$A10,d_Modelo,$B10,d_Subest,AA$7) -> 0 | AB10: =SUM(W10:AA10) -> 0 | AC10: =COUNTIFS(d_Marca,$A10,d_Modelo,$B10,d_Subest,AC$7) -> 0 | AD10: =COUNTIFS(d_Marca,$A10,d_Modelo,$B10,d_Subest,AD$7) -> 0 | AE10: =COUNTIFS(d_Marca,$A10,d_Modelo,$B10,d_Subest,AE$7) -> 0 | AF10: =COUNTIFS(d_Marca,$A10,d_Modelo,$B10,d_Subest,AF$7) -> 0 | AG10: =COUNTIFS(d_Marca,$A10,d_Modelo,$B10,d_Subest,AG$7) -> 0 | AH10: =COUNTIFS(d_Marca,$A10,d_Modelo,$B10,d_Subest,AH$7) -> 0 | AI10: =COUNTIFS(d_Marca,$A10,d_Modelo,$B10,d_Subest,AI$7) -> 0 | AJ10: =COUNTIFS(d_Marca,$A10,d_Modelo,$B10,d_Subest,AJ$7) -> 0 | ... AL10: =COUNTIFS(d_Marca,$A10,d_Modelo,$B10,d_Subest,AL$7) -> 0 | AM10: =SUM(AC10:AL10) -> 0 | AN10: =COUNTIFS(d_Marca,$A10,d_Modelo,$B10,d_Subest,AN$7) -> 0 | AO10: =COUNTIFS(d_Marca,$A10,d_Modelo,$B10,d_Subest,AO$7) -> 0 | AP10: =COUNTIFS(d_Marca,$A10,d_Modelo,$B10,d_Subest,AP$7) -> 0 | AQ10: =COUNTIFS(d_Marca,$A10,d_Modelo,$B10,d_Subest,AQ$7) -> 0 | AR10: =COUNTIFS(d_Marca,$A10,d_Modelo,$B10,d_Subest,AR$7) -> 0 | AS10: =COUNTIFS(d_Marca,$A10,d_Modelo,$B10,d_Subest,AS$7) -> 0 | AT10: =COUNTIFS(d_Marca,$A10,d_Modelo,$B10,d_Subest,AT$7) -> 0 | AU10: =COUNTIFS(d_Marca,$A10,d_Modelo,$B10,d_Subest,AU$7) -> 0 | ... AW10: =COUNTIFS(d_Marca,$A10,d_Modelo,$B10,d_Subest,AW$7) -> 0 | AX10: =SUM(AN10:AW10) -> 0 | AY10: =COUNTIFS(d_Marca,$A10,d_Modelo,$B10,d_Subest,AY$7) -> 79 | AZ10: =E10+H10+K10+P10+V10+AB10+AM10+AX10+AY10 -> 184
A11: ABB | B11: REF615A_1G | C11: =COUNTIFS(d_Marca,$A11,d_Modelo,$B11,d_Subest,C$7) -> 0 | D11: =COUNTIFS(d_Marca,$A11,d_Modelo,$B11,d_Subest,D$7) -> 0 | E11: =SUM(C11:D11) -> 0 | F11: =COUNTIFS(d_Marca,$A11,d_Modelo,$B11,d_Subest,F$7) -> 0 | G11: =COUNTIFS(d_Marca,$A11,d_Modelo,$B11,d_Subest,G$7) -> 0 | H11: =SUM(F11:G11) -> 0 | I11: =COUNTIFS(d_Marca,$A11,d_Modelo,$B11,d_Subest,I$7) -> 0 | J11: =COUNTIFS(d_Marca,$A11,d_Modelo,$B11,d_Subest,J$7) -> 0 | K11: =SUM(I11:J11) -> 0 | L11: =COUNTIFS(d_Marca,$A11,d_Modelo,$B11,d_Subest,L$7) -> 0 | M11: =COUNTIFS(d_Marca,$A11,d_Modelo,$B11,d_Subest,M$7) -> 0 | N11: =COUNTIFS(d_Marca,$A11,d_Modelo,$B11,d_Subest,N$7) -> 0 | O11: =COUNTIFS(d_Marca,$A11,d_Modelo,$B11,d_Subest,O$7) -> 0 | P11: =SUM(L11:O11) -> 0 | Q11: =COUNTIFS(d_Marca,$A11,d_Modelo,$B11,d_Subest,Q$7) -> 0 | R11: =COUNTIFS(d_Marca,$A11,d_Modelo,$B11,d_Subest,R$7) -> 0 | S11: =COUNTIFS(d_Marca,$A11,d_Modelo,$B11,d_Subest,S$7) -> 0 | T11: =COUNTIFS(d_Marca,$A11,d_Modelo,$B11,d_Subest,T$7) -> 0 | U11: =COUNTIFS(d_Marca,$A11,d_Modelo,$B11,d_Subest,U$7) -> 0 | V11: =SUM(Q11:U11) -> 0 | W11: =COUNTIFS(d_Marca,$A11,d_Modelo,$B11,d_Subest,W$7) -> 16 | X11: =COUNTIFS(d_Marca,$A11,d_Modelo,$B11,d_Subest,X$7) -> 23 | Y11: =COUNTIFS(d_Marca,$A11,d_Modelo,$B11,d_Subest,Y$7) -> 0 | Z11: =COUNTIFS(d_Marca,$A11,d_Modelo,$B11,d_Subest,Z$7) -> 14 | AA11: =COUNTIFS(d_Marca,$A11,d_Modelo,$B11,d_Subest,AA$7) -> 16 | AB11: =SUM(W11:AA11) -> 69 | AC11: =COUNTIFS(d_Marca,$A11,d_Modelo,$B11,d_Subest,AC$7) -> 0 | AD11: =COUNTIFS(d_Marca,$A11,d_Modelo,$B11,d_Subest,AD$7) -> 0 | AE11: =COUNTIFS(d_Marca,$A11,d_Modelo,$B11,d_Subest,AE$7) -> 0 | AF11: =COUNTIFS(d_Marca,$A11,d_Modelo,$B11,d_Subest,AF$7) -> 0 | AG11: =COUNTIFS(d_Marca,$A11,d_Modelo,$B11,d_Subest,AG$7) -> 0 | AH11: =COUNTIFS(d_Marca,$A11,d_Modelo,$B11,d_Subest,AH$7) -> 0 | AI11: =COUNTIFS(d_Marca,$A11,d_Modelo,$B11,d_Subest,AI$7) -> 0 | AJ11: =COUNTIFS(d_Marca,$A11,d_Modelo,$B11,d_Subest,AJ$7) -> 0 | ... AL11: =COUNTIFS(d_Marca,$A11,d_Modelo,$B11,d_Subest,AL$7) -> 0 | AM11: =SUM(AC11:AL11) -> 0 | AN11: =COUNTIFS(d_Marca,$A11,d_Modelo,$B11,d_Subest,AN$7) -> 0 | AO11: =COUNTIFS(d_Marca,$A11,d_Modelo,$B11,d_Subest,AO$7) -> 14 | AP11: =COUNTIFS(d_Marca,$A11,d_Modelo,$B11,d_Subest,AP$7) -> 0 | AQ11: =COUNTIFS(d_Marca,$A11,d_Modelo,$B11,d_Subest,AQ$7) -> 0 | AR11: =COUNTIFS(d_Marca,$A11,d_Modelo,$B11,d_Subest,AR$7) -> 0 | AS11: =COUNTIFS(d_Marca,$A11,d_Modelo,$B11,d_Subest,AS$7) -> 19 | AT11: =COUNTIFS(d_Marca,$A11,d_Modelo,$B11,d_Subest,AT$7) -> 0 | AU11: =COUNTIFS(d_Marca,$A11,d_Modelo,$B11,d_Subest,AU$7) -> 0 | ... AW11: =COUNTIFS(d_Marca,$A11,d_Modelo,$B11,d_Subest,AW$7) -> 39 | AX11: =SUM(AN11:AW11) -> 98 | AY11: =COUNTIFS(d_Marca,$A11,d_Modelo,$B11,d_Subest,AY$7) -> 0 | AZ11: =E11+H11+K11+P11+V11+AB11+AM11+AX11+AY11 -> 167
A12: ABB | B12: 1AMEBCADNEC5BNN11G | C12: =COUNTIFS(d_Marca,$A12,d_Modelo,$B12,d_Subest,C$7) -> 0 | D12: =COUNTIFS(d_Marca,$A12,d_Modelo,$B12,d_Subest,D$7) -> 1 | E12: =SUM(C12:D12) -> 1 | F12: =COUNTIFS(d_Marca,$A12,d_Modelo,$B12,d_Subest,F$7) -> 9 | G12: =COUNTIFS(d_Marca,$A12,d_Modelo,$B12,d_Subest,G$7) -> 5 | H12: =SUM(F12:G12) -> 14 | I12: =COUNTIFS(d_Marca,$A12,d_Modelo,$B12,d_Subest,I$7) -> 0 | J12: =COUNTIFS(d_Marca,$A12,d_Modelo,$B12,d_Subest,J$7) -> 0 | K12: =SUM(I12:J12) -> 0 | L12: =COUNTIFS(d_Marca,$A12,d_Modelo,$B12,d_Subest,L$7) -> 0 | M12: =COUNTIFS(d_Marca,$A12,d_Modelo,$B12,d_Subest,M$7) -> 0 | N12: =COUNTIFS(d_Marca,$A12,d_Modelo,$B12,d_Subest,N$7) -> 0 | O12: =COUNTIFS(d_Marca,$A12,d_Modelo,$B12,d_Subest,O$7) -> 0 | P12: =SUM(L12:O12) -> 0 | Q12: =COUNTIFS(d_Marca,$A12,d_Modelo,$B12,d_Subest,Q$7) -> 0 | R12: =COUNTIFS(d_Marca,$A12,d_Modelo,$B12,d_Subest,R$7) -> 0 | S12: =COUNTIFS(d_Marca,$A12,d_Modelo,$B12,d_Subest,S$7) -> 0 | T12: =COUNTIFS(d_Marca,$A12,d_Modelo,$B12,d_Subest,T$7) -> 0 | U12: =COUNTIFS(d_Marca,$A12,d_Modelo,$B12,d_Subest,U$7) -> 0 | V12: =SUM(Q12:U12) -> 0 | W12: =COUNTIFS(d_Marca,$A12,d_Modelo,$B12,d_Subest,W$7) -> 0 | X12: =COUNTIFS(d_Marca,$A12,d_Modelo,$B12,d_Subest,X$7) -> 0 | Y12: =COUNTIFS(d_Marca,$A12,d_Modelo,$B12,d_Subest,Y$7) -> 0 | Z12: =COUNTIFS(d_Marca,$A12,d_Modelo,$B12,d_Subest,Z$7) -> 0 | AA12: =COUNTIFS(d_Marca,$A12,d_Modelo,$B12,d_Subest,AA$7) -> 0 | AB12: =SUM(W12:AA12) -> 0 | AC12: =COUNTIFS(d_Marca,$A12,d_Modelo,$B12,d_Subest,AC$7) -> 0 | AD12: =COUNTIFS(d_Marca,$A12,d_Modelo,$B12,d_Subest,AD$7) -> 0 | AE12: =COUNTIFS(d_Marca,$A12,d_Modelo,$B12,d_Subest,AE$7) -> 0 | AF12: =COUNTIFS(d_Marca,$A12,d_Modelo,$B12,d_Subest,AF$7) -> 0 | AG12: =COUNTIFS(d_Marca,$A12,d_Modelo,$B12,d_Subest,AG$7) -> 0 | AH12: =COUNTIFS(d_Marca,$A12,d_Modelo,$B12,d_Subest,AH$7) -> 0 | AI12: =COUNTIFS(d_Marca,$A12,d_Modelo,$B12,d_Subest,AI$7) -> 0 | AJ12: =COUNTIFS(d_Marca,$A12,d_Modelo,$B12,d_Subest,AJ$7) -> 0 | ... AL12: =COUNTIFS(d_Marca,$A12,d_Modelo,$B12,d_Subest,AL$7) -> 0 | AM12: =SUM(AC12:AL12) -> 0 | AN12: =COUNTIFS(d_Marca,$A12,d_Modelo,$B12,d_Subest,AN$7) -> 0 | AO12: =COUNTIFS(d_Marca,$A12,d_Modelo,$B12,d_Subest,AO$7) -> 0 | AP12: =COUNTIFS(d_Marca,$A12,d_Modelo,$B12,d_Subest,AP$7) -> 0 | AQ12: =COUNTIFS(d_Marca,$A12,d_Modelo,$B12,d_Subest,AQ$7) -> 0 | AR12: =COUNTIFS(d_Marca,$A12,d_Modelo,$B12,d_Subest,AR$7) -> 0 | AS12: =COUNTIFS(d_Marca,$A12,d_Modelo,$B12,d_Subest,AS$7) -> 0 | AT12: =COUNTIFS(d_Marca,$A12,d_Modelo,$B12,d_Subest,AT$7) -> 0 | AU12: =COUNTIFS(d_Marca,$A12,d_Modelo,$B12,d_Subest,AU$7) -> 0 | ... AW12: =COUNTIFS(d_Marca,$A12,d_Modelo,$B12,d_Subest,AW$7) -> 0 | AX12: =SUM(AN12:AW12) -> 0 | AY12: =COUNTIFS(d_Marca,$A12,d_Modelo,$B12,d_Subest,AY$7) -> 70 | AZ12: =E12+H12+K12+P12+V12+AB12+AM12+AX12+AY12 -> 85
A13: ABB | B13: REF | C13: =COUNTIFS(d_Marca,$A13,d_Modelo,$B13,d_Subest,C$7) -> 0 | D13: =COUNTIFS(d_Marca,$A13,d_Modelo,$B13,d_Subest,D$7) -> 0 | E13: =SUM(C13:D13) -> 0 | F13: =COUNTIFS(d_Marca,$A13,d_Modelo,$B13,d_Subest,F$7) -> 0 | G13: =COUNTIFS(d_Marca,$A13,d_Modelo,$B13,d_Subest,G$7) -> 0 | H13: =SUM(F13:G13) -> 0 | I13: =COUNTIFS(d_Marca,$A13,d_Modelo,$B13,d_Subest,I$7) -> 0 | J13: =COUNTIFS(d_Marca,$A13,d_Modelo,$B13,d_Subest,J$7) -> 29 | K13: =SUM(I13:J13) -> 29 | L13: =COUNTIFS(d_Marca,$A13,d_Modelo,$B13,d_Subest,L$7) -> 11 | M13: =COUNTIFS(d_Marca,$A13,d_Modelo,$B13,d_Subest,M$7) -> 0 | N13: =COUNTIFS(d_Marca,$A13,d_Modelo,$B13,d_Subest,N$7) -> 0 | O13: =COUNTIFS(d_Marca,$A13,d_Modelo,$B13,d_Subest,O$7) -> 0 | P13: =SUM(L13:O13) -> 11 | Q13: =COUNTIFS(d_Marca,$A13,d_Modelo,$B13,d_Subest,Q$7) -> 0 | R13: =COUNTIFS(d_Marca,$A13,d_Modelo,$B13,d_Subest,R$7) -> 0 | S13: =COUNTIFS(d_Marca,$A13,d_Modelo,$B13,d_Subest,S$7) -> 0 | T13: =COUNTIFS(d_Marca,$A13,d_Modelo,$B13,d_Subest,T$7) -> 23 | U13: =COUNTIFS(d_Marca,$A13,d_Modelo,$B13,d_Subest,U$7) -> 0 | V13: =SUM(Q13:U13) -> 23 | W13: =COUNTIFS(d_Marca,$A13,d_Modelo,$B13,d_Subest,W$7) -> 0 | X13: =COUNTIFS(d_Marca,$A13,d_Modelo,$B13,d_Subest,X$7) -> 0 | Y13: =COUNTIFS(d_Marca,$A13,d_Modelo,$B13,d_Subest,Y$7) -> 0 | Z13: =COUNTIFS(d_Marca,$A13,d_Modelo,$B13,d_Subest,Z$7) -> 0 | AA13: =COUNTIFS(d_Marca,$A13,d_Modelo,$B13,d_Subest,AA$7) -> 0 | AB13: =SUM(W13:AA13) -> 0 | AC13: =COUNTIFS(d_Marca,$A13,d_Modelo,$B13,d_Subest,AC$7) -> 0 | AD13: =COUNTIFS(d_Marca,$A13,d_Modelo,$B13,d_Subest,AD$7) -> 0 | AE13: =COUNTIFS(d_Marca,$A13,d_Modelo,$B13,d_Subest,AE$7) -> 0 | AF13: =COUNTIFS(d_Marca,$A13,d_Modelo,$B13,d_Subest,AF$7) -> 4 | AG13: =COUNTIFS(d_Marca,$A13,d_Modelo,$B13,d_Subest,AG$7) -> 0 | AH13: =COUNTIFS(d_Marca,$A13,d_Modelo,$B13,d_Subest,AH$7) -> 0 | AI13: =COUNTIFS(d_Marca,$A13,d_Modelo,$B13,d_Subest,AI$7) -> 0 | AJ13: =COUNTIFS(d_Marca,$A13,d_Modelo,$B13,d_Subest,AJ$7) -> 0 | ... AL13: =COUNTIFS(d_Marca,$A13,d_Modelo,$B13,d_Subest,AL$7) -> 0 | AM13: =SUM(AC13:AL13) -> 4 | AN13: =COUNTIFS(d_Marca,$A13,d_Modelo,$B13,d_Subest,AN$7) -> 0 | AO13: =COUNTIFS(d_Marca,$A13,d_Modelo,$B13,d_Subest,AO$7) -> 0 | AP13: =COUNTIFS(d_Marca,$A13,d_Modelo,$B13,d_Subest,AP$7) -> 0 | AQ13: =COUNTIFS(d_Marca,$A13,d_Modelo,$B13,d_Subest,AQ$7) -> 0 | AR13: =COUNTIFS(d_Marca,$A13,d_Modelo,$B13,d_Subest,AR$7) -> 0 | AS13: =COUNTIFS(d_Marca,$A13,d_Modelo,$B13,d_Subest,AS$7) -> 0 | AT13: =COUNTIFS(d_Marca,$A13,d_Modelo,$B13,d_Subest,AT$7) -> 0 | AU13: =COUNTIFS(d_Marca,$A13,d_Modelo,$B13,d_Subest,AU$7) -> 0 | ... AW13: =COUNTIFS(d_Marca,$A13,d_Modelo,$B13,d_Subest,AW$7) -> 0 | AX13: =SUM(AN13:AW13) -> 0 | AY13: =COUNTIFS(d_Marca,$A13,d_Modelo,$B13,d_Subest,AY$7) -> 0 | AZ13: =E13+H13+K13+P13+V13+AB13+AM13+AX13+AY13 -> 67
