Workbook

Sheet Resumen por sector
A1: CENSO DE UPS (SFI) POR SECTOR — REFINERÍA OLMECA · SICM ELÉCTRICO
A2: Fuente: censo maestro SAP (data/normalized/equipos.json, familia baterías). Una fila por banco de baterías de SFI; la potencia es la "potencia nominal" registrada en SAP.
A4: Sector | B4: N° SFI (UPS) | C4: Con kVA en SAP | D4: Sin kVA en SAP | E4: % sin dato | F4: Potencia instalada (kVA) | G4: kVA máx. unitario | H4: kVA promedio | I4: Autonomía mín. (h) | J4: Autonomía máx. (h) | K4: Plantas / áreas
A5: 1 | B5: =COUNTIFS(Detalle!$A$2:$A$86,A5) | C5: =COUNTIFS(Detalle!$A$2:$A$86,A5,Detalle!$E$2:$E$86,">0") | D5: =B5-C5 | E5: =IF(B5=0,0,D5/B5) | F5: =SUMIFS(Detalle!$E$2:$E$86,Detalle!$A$2:$A$86,A5) | G5: =MAXIFS(Detalle!$E$2:$E$86,Detalle!$A$2:$A$86,A5) | H5: =IF(C5=0,0,F5/C5) | I5: =MINIFS(Detalle!$G$2:$G$86,Detalle!$A$2:$A$86,A5,Detalle!$G$2:$G$86,">0") | J5: =MAXIFS(Detalle!$G$2:$G$86,Detalle!$A$2:$A$86,A5) | K5: U-De Destilación Combinada (UDC1) Tren 1; U-De Destilación Combinada (UDC2) Tren 2
A6: 2 | B6: =COUNTIFS(Detalle!$A$2:$A$86,A6) | C6: =COUNTIFS(Detalle!$A$2:$A$86,A6,Detalle!$E$2:$E$86,">0") | D6: =B6-C6 | E6: =IF(B6=0,0,D6/B6) | F6: =SUMIFS(Detalle!$E$2:$E$86,Detalle!$A$2:$A$86,A6) | G6: =MAXIFS(Detalle!$E$2:$E$86,Detalle!$A$2:$A$86,A6) | H6: =IF(C6=0,0,F6/C6) | I6: =MINIFS(Detalle!$G$2:$G$86,Detalle!$A$2:$A$86,A6,Detalle!$G$2:$G$86,">0") | J6: =MAXIFS(Detalle!$G$2:$G$86,Detalle!$A$2:$A$86,A6) | K6: U-De Coquización Retardada
A7: 3 | B7: =COUNTIFS(Detalle!$A$2:$A$86,A7) | C7: =COUNTIFS(Detalle!$A$2:$A$86,A7,Detalle!$E$2:$E$86,">0") | D7: =B7-C7 | E7: =IF(B7=0,0,D7/B7) | F7: =SUMIFS(Detalle!$E$2:$E$86,Detalle!$A$2:$A$86,A7) | G7: =MAXIFS(Detalle!$E$2:$E$86,Detalle!$A$2:$A$86,A7) | H7: =IF(C7=0,0,F7/C7) | I7: =MINIFS(Detalle!$G$2:$G$86,Detalle!$A$2:$A$86,A7,Detalle!$G$2:$G$86,">0") | J7: =MAXIFS(Detalle!$G$2:$G$86,Detalle!$A$2:$A$86,A7) | K7: U-De Alquilación (Alky1)
A8: 4 | B8: =COUNTIFS(Detalle!$A$2:$A$86,A8) | C8: =COUNTIFS(Detalle!$A$2:$A$86,A8,Detalle!$E$2:$E$86,">0") | D8: =B8-C8 | E8: =IF(B8=0,0,D8/B8) | F8: =SUMIFS(Detalle!$E$2:$E$86,Detalle!$A$2:$A$86,A8) | G8: =MAXIFS(Detalle!$E$2:$E$86,Detalle!$A$2:$A$86,A8) | H8: =IF(C8=0,0,F8/C8) | I8: =MINIFS(Detalle!$G$2:$G$86,Detalle!$A$2:$A$86,A8,Detalle!$G$2:$G$86,">0") | J8: =MAXIFS(Detalle!$G$2:$G$86,Detalle!$A$2:$A$86,A8) | K8: U-Generadora De Hidrógeno (Ph21) Tren 1
A9: 5 | B9: =COUNTIFS(Detalle!$A$2:$A$86,A9) | C9: =COUNTIFS(Detalle!$A$2:$A$86,A9,Detalle!$E$2:$E$86,">0") | D9: =B9-C9 | E9: =IF(B9=0,0,D9/B9) | F9: =SUMIFS(Detalle!$E$2:$E$86,Detalle!$A$2:$A$86,A9) | G9: =MAXIFS(Detalle!$E$2:$E$86,Detalle!$A$2:$A$86,A9) | H9: =IF(C9=0,0,F9/C9) | I9: =MINIFS(Detalle!$G$2:$G$86,Detalle!$A$2:$A$86,A9,Detalle!$G$2:$G$86,">0") | J9: =MAXIFS(Detalle!$G$2:$G$86,Detalle!$A$2:$A$86,A9) | K9: U-Isomerizadora Pentanos/Hexanos (Pnx1); U-Tratamiento/Recuperación Gas (Ptrg1)
A10: 6 | B10: =COUNTIFS(Detalle!$A$2:$A$86,A10) | C10: =COUNTIFS(Detalle!$A$2:$A$86,A10,Detalle!$E$2:$E$86,">0") | D10: =B10-C10 | E10: =IF(B10=0,0,D10/B10) | F10: =SUMIFS(Detalle!$E$2:$E$86,Detalle!$A$2:$A$86,A10) | G10: =MAXIFS(Detalle!$E$2:$E$86,Detalle!$A$2:$A$86,A10) | H10: =IF(C10=0,0,F10/C10) | I10: =MINIFS(Detalle!$G$2:$G$86,Detalle!$A$2:$A$86,A10,Detalle!$G$2:$G$86,">0") | J10: =MAXIFS(Detalle!$G$2:$G$86,Detalle!$A$2:$A$86,A10) | K10: Bunker; Edificio Administrativo Sur; Laboratorio Quimico; Planta De Tto De Aguas Amargas Comun; U-De Tratamiento De Amina Area Comun; U-Recuperadora De Azufre (Pra1) Tren 1
A11: 7 | B11: =COUNTIFS(Detalle!$A$2:$A$86,A11) | C11: =COUNTIFS(Detalle!$A$2:$A$86,A11,Detalle!$E$2:$E$86,">0") | D11: =B11-C11 | E11: =IF(B11=0,0,D11/B11) | F11: =SUMIFS(Detalle!$E$2:$E$86,Detalle!$A$2:$A$86,A11) | G11: =MAXIFS(Detalle!$E$2:$E$86,Detalle!$A$2:$A$86,A11) | H11: =IF(C11=0,0,F11/C11) | I11: =MINIFS(Detalle!$G$2:$G$86,Detalle!$A$2:$A$86,A11,Detalle!$G$2:$G$86,">0") | J11: =MAXIFS(Detalle!$G$2:$G$86,Detalle!$A$2:$A$86,A11) | K11: Carcamo Sur; Planta De Tratamiento De Efluentes
A12: 8 | B12: =COUNTIFS(Detalle!$A$2:$A$86,A12) | C12: =COUNTIFS(Detalle!$A$2:$A$86,A12,Detalle!$E$2:$E$86,">0") | D12: =B12-C12 | E12: =IF(B12=0,0,D12/B12) | F12: =SUMIFS(Detalle!$E$2:$E$86,Detalle!$A$2:$A$86,A12) | G12: =MAXIFS(Detalle!$E$2:$E$86,Detalle!$A$2:$A$86,A12) | H12: =IF(C12=0,0,F12/C12) | I12: =MINIFS(Detalle!$G$2:$G$86,Detalle!$A$2:$A$86,A12,Detalle!$G$2:$G$86,">0") | J12: =MAXIFS(Detalle!$G$2:$G$86,Detalle!$A$2:$A$86,A12) | K12: Arranque Negro; Planta De Cogeneración; Pretratamiento De Agua; Seccion De Contraincendio; Seccion Torre De Enfriamiento Ct-00201; Seccion Torre De Enfriamiento Ct-00202; Seccion Torre De Enfriamiento Ct-00203; Servicios Complementarios; Suministro De Agua Cruda; Unidad Desmineralizadora De Agua
A13: TALLERES | B13: =COUNTIFS(Detalle!$A$2:$A$86,A13) | C13: =COUNTIFS(Detalle!$A$2:$A$86,A13,Detalle!$E$2:$E$86,">0") | D13: =B13-C13 | E13: =IF(B13=0,0,D13/B13) | F13: =SUMIFS(Detalle!$E$2:$E$86,Detalle!$A$2:$A$86,A13) | G13: =MAXIFS(Detalle!$E$2:$E$86,Detalle!$A$2:$A$86,A13) | H13: =IF(C13=0,0,F13/C13) | I13: =MINIFS(Detalle!$G$2:$G$86,Detalle!$A$2:$A$86,A13,Detalle!$G$2:$G$86,">0") | J13: =MAXIFS(Detalle!$G$2:$G$86,Detalle!$A$2:$A$86,A13) | K13: Central Ci; Edificio Administrativo Norte; Edificio Administrativo Sur; Edificio Telecom
A14: TOTAL | B14: =SUM(B5:B13) | C14: =SUM(C5:C13) | D14: =SUM(D5:D13) | E14: =D14/B14 | F14: =SUM(F5:F13) | G14: =MAX(G5:G13) | H14: =F14/C14 | I14: =MIN(I5:I13) | J14: =MAX(J5:J13)
A16: Lectura: el kVA instalado solo suma las unidades con dato en SAP; el sector con muchas unidades sin kVA subestima su potencia real.

Sheet Detalle
A1: Sector | B1: Planta / área | C1: TAG banco (SFI) | D1: SAP | E1: Potencia SFI (kVA) | F1: Capacidad banco (Ah) | G1: Autonomía (h) | H1: Corriente salida rect. (A) | I1: V salida (Vcc) | J1: V flotación (Vcc) | K1: N° celdas | L1: Tipo batería | M1: Marca | N1: Modelo | O1: Fases entrada | P1: V entrada (V) | Q1: Observación de dato | R1: Estado recorrido 02/10/26 | S1: Carga medida 02/10 (kVA)
A2: 1 | B2: U-DE DESTILACIÓN COMBINADA (UDC1) TREN 1 | C2: BB-SFI-12_1-01 | D2: 20939882 | E2: 80 | F2: 1350 | G2: 1.5 | H2: 800 | I2: 125 | J2: 143 | K2: 100 | L2: NIQUEL-CADMIO | M2: GAZ | N2: KGM 1350 P | O2: 3 | P2: 480 | R2: Fuera de servicio (bypass externo)
A3: 1 | B3: U-DE DESTILACIÓN COMBINADA (UDC1) TREN 1 | C3: BB-SFI-12_1-SCD/TEL | D3: 20939884 | E3: 80 | F3: 950 | G3: 0.5 | H3: 800 | I3: 125 | J3: 143 | K3: 100 | L3: NIQUEL-CADMIO | M3: GAZ | N3: KGM 950 P | O3: 3 | P3: 480 | R3: En operación | S3: 11.136
A4: 1 | B4: U-DE DESTILACIÓN COMBINADA (UDC1) TREN 1 | C4: BB-SFI-12_1-SIS/F&G | D4: 20939319 | E4: 60 | F4: 690 | G4: 0.5 | H4: 491 | I4: 125 | J4: 143 | K4: 100 | L4: NIQUEL-CADMIO | M4: GAZ | N4: KGM 690 P | O4: 3 | P4: 480 | R4: En operación | S4: 8.448
A5: 1 | B5: U-DE DESTILACIÓN COMBINADA (UDC2) TREN 2 | C5: BB-SFI-12-01 | D5: 20939874 | E5: 80 | F5: 1350 | G5: 1.5 | H5: 800 | I5: 125 | J5: 143 | K5: 100 | L5: NIQUEL-CADMIO | M5: GAZ | N5: KGM 1350P | O5: 3 | P5: 480
A6: 1 | B6: U-DE DESTILACIÓN COMBINADA (UDC2) TREN 2 | C6: BB-SFI-12-SCD/TEL | D6: 20939877 | E6: 100 | F6: 1000 | G6: 0.5 | H6: 800 | I6: 125 | J6: 143 | K6: 100 | L6: NIQUEL-CADMIO | M6: GAZ | N6: KGM 1000P | O6: 3 | P6: 480
A7: 1 | B7: U-DE DESTILACIÓN COMBINADA (UDC2) TREN 2 | C7: BB-SFI-12-SIS/F&G | D7: 20939878 | E7: 80 | F7: 800 | G7: 0.5 | H7: 600 | I7: 125 | J7: 143 | K7: 100 | L7: NIQUEL-CADMIO | M7: GAZ | N7: KGM 800P | O7: 3 | P7: 480
A8: 2 | B8: U-DE COQUIZACIÓN RETARDADA | C8: BB-SFI-15-01 | D8: 21002323 | L8: NI-CAD | M8: ALCAD | N8: VTX IL 1030-1 | O8: 3 | Q8: Sin kVA en SAP; Sin Ah
A9: 2 | B9: U-DE COQUIZACIÓN RETARDADA | C9: BB-SFI-15-02 | D9: 21002322 | L9: NI-CAD | M9: ALCAD | N9: VTX IM 1030-1 | O9: 3 | Q9: Sin kVA en SAP; Sin Ah
A10: 2 | B10: U-DE COQUIZACIÓN RETARDADA | C10: BB-SFI-151-01 | D10: 21002321 | L10: NI-CAD | M10: ALCAD VANTEX | N10: ALCAD VTX IM 785-1 | O10: 3 | Q10: Sin kVA en SAP; Sin Ah
A11: 2 | B11: U-DE COQUIZACIÓN RETARDADA | C11: BB-SFI-151-02 | D11: 21002324 | L11: NI-CAD | M11: ALCAD | N11: VTX IM 170-5 | O11: 3 | Q11: Sin kVA en SAP; Sin Ah
A12: 2 | B12: U-DE COQUIZACIÓN RETARDADA | C12: BB-SFI-151-03 | D12: 21002325 | F12: 540 | L12: NI-CAD | M12: ALCAD | N12: ALCAD VANTEX VTX IM 540-1 | O12: 3 | Q12: Sin kVA en SAP
A13: 2 | B13: U-DE COQUIZACIÓN RETARDADA | C13: BB-SFI-151-04 | D13: 21002326 | F13: 785 | L13: NI-CAD | M13: ALCAD | N13: ALCAD VTX IM 785-1 | O13: 3 | Q13: Sin kVA en SAP
A14: 2 | B14: U-DE COQUIZACIÓN RETARDADA | C14: BB-SFI-CCS-SCD-TEL | D14: 21002330 | F14: 490 | L14: NI-CAD | M14: ALCAD | N14: VTX IM 490-1 | O14: 3 | Q14: Sin kVA en SAP
A15: 2 | B15: U-DE COQUIZACIÓN RETARDADA | C15: BB-SFI-CCS-SIS/F&G | D15: 21002331 | E15: 30 | F15: 420 | G15: 0.5 | H15: 256 | I15: 125 | J15: 135 | K15: 100 | L15: NIQUEL-CADMIO | M15: ALCAD | N15: VTX IM 420-3 | O15: 3 | P15: 480
A16: 3 | B16: U-DE ALQUILACIÓN (ALKY1) | C16: BB-SFI-14-01 | D16: 20939938 | E16: 43 | F16: 1230 | G16: 1.5 | H16: 150 | I16: 125 | J16: 1.4 | K16: 96 | L16: NIQUEL-CADMIO | M16: SAFT | N16: UP1M 1230-1 | O16: 3 | P16: 480 | Q16: kVA no comercial: validar placa
A17: 3 | B17: U-DE ALQUILACIÓN (ALKY1) | C17: BB-SFI-14-02 | D17: 20939939 | E17: 41 | F17: 395 | G17: 1.5 | H17: 150 | I17: 127 | J17: 1.4 | K17: 96 | L17: NIQUEL-CADMIO | M17: SAFT | N17: UP1M 395-3 | O17: 3 | P17: 480 | Q17: kVA no comercial: validar placa
A18: 3 | B18: U-DE ALQUILACIÓN (ALKY1) | C18: BB-SFI-SAT-SCD/TEL-02 | D18: 20939933 | E18: 60 | F18: 690 | G18: 0.5 | H18: 158 | I18: 125 | J18: 143 | K18: 100 | L18: NIQUEL-CADMIO | M18: SAFT | N18: UP1M 690-1 | O18: 3 | P18: 480
A19: 3 | B19: U-DE ALQUILACIÓN (ALKY1) | C19: BB-SFI-SAT-SIS/F&-G-02 | D19: 20939934 | E19: 40 | F19: 490 | G19: 0.5 | H19: 105 | I19: 125 | J19: 141 | K19: 99 | L19: NIQUEL-CADMIO | M19: SAFT | N19: UP1M 490-1 | O19: 3 | P19: 480
A20: 4 | B20: U-GENERADORA DE HIDRÓGENO (PH21) TREN 1 | C20: BB-SFI-23-01 | D20: 20994505 | E20: 50 | F20: 950 | G20: 5 | H20: 125 | I20: 220 | J20: 142 | K20: 100 | L20: NIQUEL-CADMIO | M20: GAZ | N20: KGM 950P | O20: 3 | P20: 480
A21: 4 | B21: U-GENERADORA DE HIDRÓGENO (PH21) TREN 1 | C21: BB-SFI-CCS-F&G/ESD | D21: 20939989 | F21: 300 | G21: 0.5 | I21: 125 | J21: 145 | K21: 100 | L21: NI-CD | M21: GAZ | N21: KGM300P | O21: 3 | P21: 480 | Q21: Sin kVA en SAP
A22: 4 | B22: U-GENERADORA DE HIDRÓGENO (PH21) TREN 1 | C22: BB-SFI-CCS-SCD/TEL-S04 | D22: 20939990 | F22: 380 | G22: 0.5 | I22: 125 | J22: 145 | K22: 100 | L22: NI-CD | M22: GAZ | N22: KGM380P | O22: 3 | P22: 480 | Q22: Sin kVA en SAP
A23: 5 | B23: U-ISOMERIZADORA PENTANOS/HEXANOS (PNX1) | C23: BB-SFI SATSIS/F&G-01 | D23: 20940003 | F23: 245 | G23: 5 | H23: 160 | I23: 125 | J23: 141 | K23: 99 | L23: NIQUEL-CADMIO | M23: SAFT | N23: UP1M.245-2 | O23: 3 | P23: 480 | Q23: Sin kVA en SAP
A24: 5 | B24: U-ISOMERIZADORA PENTANOS/HEXANOS (PNX1) | C24: BB-SFI06-01 | D24: 20940002 | F24: 785 | G24: 5 | H24: 160 | I24: 125 | J24: 143 | K24: 100 | L24: NIQUEL-CADMIO | M24: SAFT | N24: UPM-785 | O24: 3 | P24: 480 | Q24: Sin kVA en SAP
A25: 5 | B25: U-TRATAMIENTO/RECUPERACIÓN GAS (PTRG1) | C25: BB SFI-05-01 | D25: 20939998 | F25: 550 | G25: 1.5 | H25: 160 | I25: 125 | J25: 140 | K25: 94 | L25: NIQUEL-CADMIO | M25: SAFT | N25: VGM 550 | O25: 3 | P25: 480 | Q25: Sin kVA en SAP
A26: 5 | B26: U-TRATAMIENTO/RECUPERACIÓN GAS (PTRG1) | C26: BBSFI-CCS-ESD/F&G | D26: 20994321 | G26: 0.5 | I26: 125 | K26: 187 | L26: NIQUEL-CADMIO | M26: VGM | N26: VGM 250 | O26: 3 | Q26: Sin kVA en SAP; Sin Ah
A27: 5 | B27: U-TRATAMIENTO/RECUPERACIÓN GAS (PTRG1) | C27: BBSFI-CCS-SCD/TEL | D27: 20994320 | G27: 0.5 | I27: 125 | K27: 187 | L27: NIQUEL-CADMIO | M27: VGM | N27: VGM 355 | O27: 3 | Q27: Sin kVA en SAP; Sin Ah
A28: 6 | B28: BUNKER | C28: BB-CCC-10 | D28: 20940226 | E28: 20 | F28: 540 | G28: 2 | H28: 53 | I28: 125 | J28: 140 | K28: 100 | L28: NIQUEL-CADMIO | M28: ALCAD VANTEX | N28: VTX 1M 540 – 1 | O28: 3 | P28: 480
A29: 6 | B29: BUNKER | C29: BB-CCC-15 | D29: 20940231 | E29: 5 | F29: 150 | G29: 2 | H29: 42 | I29: 125 | J29: 140 | K29: 100 | L29: NIQUEL-CADMIO | M29: ALCAD VANTEX | N29: VTX 1M 150 – 5 | O29: 3 | P29: 480
A30: 6 | B30: BUNKER | C30: BB-CCC-16 | D30: 20940232 | E30: 20 | F30: 540 | G30: 2 | H30: 53 | I30: 125 | J30: 140 | K30: 100 | L30: NIQUEL-CADMIO | M30: ALCAD VANTEX | N30: VTX 1M 540 – 1 | O30: 3 | P30: 480
A31: 6 | B31: BUNKER | C31: BB-CCC-17 SECT | D31: 20940233 | E31: 20 | F31: 540 | G31: 2 | H31: 53 | I31: 125 | J31: 140 | K31: 100 | L31: NIQUEL-CADMIO | M31: ALCAD VANTEX | N31: VTX 1M 540 – 1 | O31: 3 | P31: 480
A32: 6 | B32: BUNKER | C32: BB-CCC-18 TELE | D32: 20940234 | E32: 100 | F32: 1380 | G32: 2 | H32: 263 | I32: 125 | J32: 140 | K32: 182 | L32: NIQUEL-CADMIO | M32: ALCAD VANTEX | N32: VTX 1M 1380 - 1 | O32: 3 | P32: 480
A33: 6 | B33: BUNKER | C33: BB-CCC-19 ALUM | D33: 20940235 | E33: 30 | F33: 640 | G33: 1.5 | H33: 79 | I33: 125 | J33: 140 | K33: 100 | L33: NIQUEL-CADMIO | M33: ALCAD VANTEX | N33: VTX 1M 640 – 1 | O33: 3 | P33: 480
A34: 6 | B34: EDIFICIO ADMINISTRATIVO SUR | C34: BBSFI-29-01 | D34: 20940210 | E34: 7.5 | F34: 140 | G34: 0.5 | H34: 151 | I34: 125 | J34: 135 | K34: 100 | L34: NIQUEL-CADMIO | M34: POWER SAFE ENERSYS | N34: VGM 140 | O34: 3 | P34: 480
A35: 6 | B35: EDIFICIO ADMINISTRATIVO SUR | C35: BBSFI-29-TEL/F&G | D35: 20940211 | E35: 15 | F35: 185 | G35: 0.5 | H35: 151 | I35: 125 | J35: 135 | K35: 100 | L35: NIQUEL-CADMIO | M35: POWER SAFE ENERSYS | N35: VGM 185 | O35: 3 | P35: 480
A36: 6 | B36: LABORATORIO QUIMICO | C36: BB-SFI-113-01 | D36: 20994542 | E36: 15 | F36: 320 | G36: 5 | H36: 64 | I36: 125 | J36: 142 | K36: 100 | L36: NIQUEL-CADMIO | N36: VTX 1M320-2/VTX 1M320-2 | O36: 3 | P36: 480
A37: 6 | B37: LABORATORIO QUIMICO | C37: BB-SFI-113-02 | D37: 20994543 | E37: 10 | F37: 150 | G37: 5 | H37: 30 | I37: 125 | J37: 137.7 | K37: 97 | L37: NIQUEL-CADMIO | N37: VTX 1M150-6/150-5/150-4 | O37: 3 | P37: 480
A38: 6 | B38: PLANTA DE TTO DE AGUAS AMARGAS COMUN | C38: BB-SFI-08-AL-01 | D38: 20940179 | E38: 25 | F38: 445 | G38: 1.5 | H38: 413 | I38: 125 | J38: 135 | K38: 100 | L38: NIQUEL-CADMIO | M38: SAFT NIFE | N38: UP1M 445-2 | O38: 3 | P38: 480
A39: 6 | B39: PLANTA DE TTO DE AGUAS AMARGAS COMUN | C39: BB-SFI-CCS-SCD/TEL-S06 | D39: 20940166 | E39: 40 | F39: 420 | G39: 0.5 | H39: 341 | I39: 125 | J39: 135 | K39: 100 | L39: NIQUEL-CADMIO | M39: SAFT NIFE | N39: UP1M 420-2 | O39: 3 | P39: 480
A40: 6 | B40: U-DE TRATAMIENTO DE AMINA AREA COMUN | C40: BB-SFI-09-AL-01 | D40: 20940187 | E40: 30 | F40: 540 | G40: 1.5 | H40: 242.6 | I40: 125 | J40: 135 | K40: 100 | L40: NIQUEL-CADMIO | M40: SAFT NIFE | N40: UP1M 540-1 | O40: 3 | P40: 480
...

Sheet Notas
A1: MÉTODO Y LÍMITES
A2: 1. Universo: 85 bancos de baterías de SFI del censo SAP (75 con "SFI" en el TAG o denominación, más 10 con tipo de cargador "SFI": BB-CCC-10/15/16/17/18/19 y BB-1001/1002/3001/3002). Cada banco se toma como una unidad SFI.
A3: 2. SAP no tiene el UPS como objeto propio con potencia: la kVA sale del campo "potencia nominal" del banco. [Suposición] corresponde a la potencia del SFI. Se comprobó en los 2 SFI medidos el 02/10/26: SCD/TEL 80 kVA con carga 3×128 V×29 A = 11.1 kVA (13.9 %, el folio dice 13 %) y SIS/F&G 60 kVA con 8.4 kVA (14.1 %, el folio dice 14 %).
A4: 3. kVA es potencia aparente: SAP no trae factor de potencia ni kW. Los UPS con otra denominación (sin "SFI") no están en este censo.
A5: 4. Filas amarillas: sin kVA en SAP. Valores de kVA no comerciales (17.9, 26.1, 35.9, 41, 43, 65.5, 134) están marcados "validar placa".
A6: 5. Sector 2 (Coquizadora, SE-15 y SE-15-1): 7 de 8 SFI sin kVA. La inspección del 02/10/26 marcó "UPS en operación normal" sin registrar modo ni potencia.
A7: 6. Estado 02/10/26: BB-SFI-12_1-01 (UDC1) fuera de servicio, en bypass externo (fila roja).
A8: 7. La hoja Resumen usa fórmulas (COUNTIFS, SUMIFS, MAXIFS, MINIFS): requieren Excel 2019 o posterior; se recalculan al abrir.
